Workbook

Sheet Model
A1: Six Peak Capital - Financial Projections
B2: 46023 | C2: 46054 | D2: 46082 | E2: 46113 | F2: 46143 | G2: 46174 | H2: 46204 | I2: 46235 | J2: 46266 | K2: 46296 | L2: 46327 | M2: 46357 | N2: 46388 | O2: 46419 | P2: 46447 | Q2: 46478 | R2: 46508 | S2: 46539 | T2: 46569 | U2: 46600 | V2: 46631 | W2: 46661 | X2: 46692 | Y2: 46722 | Z2: 46753 | AA2: 46784 | AB2: 46813 | AC2: 46844 | AD2: 46874 | AE2: 46905 | AF2: 46935 | AG2: 46966 | AH2: 46997 | AI2: 47027 | AJ2: 47058 | AK2: 47088 | AL2: 47119 | AM2: 47150 | AN2: 47178 | AO2: 47209 | AP2: 47239 | AQ2: 47270 | AR2: 47300 | AS2: 47331 | AT2: 47362 | AU2: 47392 | AV2: 47423 | AW2: 47453 | AX2: 47484 | AY2: 47515 | AZ2: 47543 | BA2: 47574 | BB2: 47604 | BC2: 47635 | BD2: 47665 | BE2: 47696 | BF2: 47727 | BG2: 47757 | BH2: 47788 | BI2: 47818 | BJ2: 47849 | BK2: 47880 | BL2: 47908 | BM2: 47939 | BN2: 47969 | BO2: 48000 | BP2: 48030 | BQ2: 48061 | BR2: 48092 | BS2: 48122 | BT2: 48153 | BU2: 48183 | BV2: 48214 | BW2: 48245 | BX2: 48274 | BY2: 48305 | BZ2: 48335 | CA2: 48366 | CB2: 48396 | CC2: 48427 | CD2: 48458 | CE2: 48488 | CF2: 48519 | CG2: 48549 | CH2: 48580 | CI2: 48611 | CJ2: 48639 | CK2: 48670 | CL2: 48700 | CM2: 48731 | CN2: 48761 | CO2: 48792 | CP2: 48823 | CQ2: 48853 | CR2: 48884 | CS2: 48914 | CT2: 48945 | CU2: 48976 | CV2: 49004 | CW2: 49035 | CX2: 49065 | CY2: 49096 | CZ2: 49126 | DA2: 49157 | DB2: 49188 | DC2: 49218 | DD2: 49249 | DE2: 49279
A3: Month # | B3: -2 | C3: -1 | D3: 0 | E3: 1 | F3: 2 | G3: 3 | H3: 4 | I3: 5 | J3: 6 | K3: 7 | L3: 8 | M3: 9 | N3: 10 | O3: 11 | P3: 12 | Q3: 13 | R3: 14 | S3: 15 | T3: 16 | U3: 17 | V3: 18 | W3: 19 | X3: 20 | Y3: 21 | Z3: 22 | AA3: 23 | AB3: 24 | AC3: 25 | AD3: 26 | AE3: 27 | AF3: 28 | AG3: 29 | AH3: 30 | AI3: 31 | AJ3: 32 | AK3: 33 | AL3: 34 | AM3: 35 | AN3: 36 | AO3: 37 | AP3: 38 | AQ3: 39 | AR3: 40 | AS3: 41 | AT3: 42 | AU3: 43 | AV3: 44 | AW3: 45 | AX3: 46 | AY3: 47 | AZ3: 48 | BA3: 49 | BB3: 50 | BC3: 51 | BD3: 52 | BE3: 53 | BF3: 54 | BG3: 55 | BH3: 56 | BI3: 57 | BJ3: 58 | BK3: 59 | BL3: 60 | BM3: 61 | BN3: 62 | BO3: 63 | BP3: 64 | BQ3: 65 | BR3: 66 | BS3: 67 | BT3: 68 | BU3: 69 | BV3: 70 | BW3: 71 | BX3: 72 | BY3: 73 | BZ3: 74 | CA3: 75 | CB3: 76 | CC3: 77 | CD3: 78 | CE3: 79 | CF3: 80 | CG3: 81 | CH3: 82 | CI3: 83 | CJ3: 84 | CK3: 85 | CL3: 86 | CM3: 87 | CN3: 88 | CO3: 89 | CP3: 90 | CQ3: 91 | CR3: 92 | CS3: 93 | CT3: 94 | CU3: 95 | CV3: 96 | CW3: 97 | CX3: 98 | CY3: 99 | CZ3: 100 | DA3: 101 | DB3: 102 | DC3: 103 | DD3: 104 | DE3: 105
B4: =IF(ISBLANK(Actuals!C14),"","Actuals") -> Actuals | C4: =IF(ISBLANK(Actuals!D14),"","Actuals") -> Actuals | D4: =IF(ISBLANK(Actuals!E14),"","Actuals") -> Actuals | E4: =IF(ISBLANK(Actuals!F14),"","Actuals") -> Actuals | F4: =IF(ISBLANK(Actuals!G14),"","Actuals") -> Actuals | G4: =IF(ISBLANK(Actuals!H14),"","Actuals") | H4: =IF(ISBLANK(Actuals!I14),"","Actuals") | I4: =IF(ISBLANK(Actuals!J14),"","Actuals") | ... DE4: =IF(ISBLANK(Actuals!DF14),"","Actuals")
A5: YTD Actuals Snapshot:
F6: =IF(LEN(IF(Projects!$G$2="Yes",Projects!$A$2,"")&IF(Projects!$G$3="Yes",", "&Projects!$A$3,"")&IF(Projects!$G$4="Yes",", "&Projects!$A$4,"")&IF(Projects!$G$5="Yes",", "&Projects!$A$5,"")&IF(Projects!$G$6="Yes",", "&Projects!$A$6,""))>0,IF(LEFT(IF(Projects!$G$2="Yes",Projects!$A$2,"")&IF(Projects!$G$3="Yes",", "&Projects!$A$3,"")&IF(Projects!$G$4="Yes",", "&Projects!$A$4,"")&IF(Projects!$G$5="Yes",", "&Projects!$A$5,"")&IF(Projects!$G$6="Yes",", "&Projects!$A$6,""),2)=", ",MID(IF(Projects!$G$2="Yes",Projects!$A$2,"")&IF(Projects!$G$3="Yes",", "&Projects!$A$3,"")&IF(Projects!$G$4="Yes",", "&Projects!$A$4,"")&IF(Projects!$G$5="Yes",", "&Projects!$A$5,"")&IF(Projects!$G$6="Yes",", "&Projects!$A$6,""),3,1000),IF(Projects!$G$2="Yes",Projects!$A$2,"")&IF(Projects!$G$3="Yes",", "&Projects!$A$3,"")&IF(Projects!$G$4="Yes",", "&Projects!$A$4,"")&IF(Projects!$G$5="Yes",", "&Projects!$A$5,"")&IF(Projects!$G$6="Yes",", "&Projects!$A$6,"")),"") -> Crenshaw, Ramsgate, Califa, Whipple, Nelrose | H6: =IF(Projects!$G$7="Yes",Projects!$A$7,"") -> Francis | I6: =IF(Projects!$G$11="Yes",Projects!$A$11,"") -> Klump | J6: =IF(Projects!$G$12="Yes",Projects!$A$12,"") -> Scott | K6: =IF(LEN(IF(Projects!$G$8="Yes",Projects!$A$8,"")&IF(Projects!$G$9="Yes",", "&Projects!$A$9,""))>0,IF(LEFT(IF(Projects!$G$8="Yes",Projects!$A$8,"")&IF(Projects!$G$9="Yes",", "&Projects!$A$9,""),2)=", ",MID(IF(Projects!$G$8="Yes",Projects!$A$8,"")&IF(Projects!$G$9="Yes",", "&Projects!$A$9,""),3,1000),IF(Projects!$G$8="Yes",Projects!$A$8,"")&IF(Projects!$G$9="Yes",", "&Projects!$A$9,"")),"") -> Lexington, Denny | L6: =IF(Projects!$G$10="Yes",Projects!$A$10,"") -> Acama | Q6: =IF(Projects!$G$13="Yes",Projects!$A$13,"") -> Reseda | T6: =IF(Projects!$G$17="Yes",Projects!$A$17,"") | V6: =IF(Projects!$G$18="Yes",Projects!$A$18,"") | Y6: =IF(Projects!$G$19="Yes",Projects!$A$19,"") | AB6: =IF(Projects!$G$20="Yes",Projects!$A$20,"") | AE6: =IF(LEN(IF(Projects!$G$14="Yes",Projects!$A$14,"")&IF(Projects!$G$21="Yes",", "&Projects!$A$21,""))>0,IF(LEFT(IF(Projects!$G$14="Yes",Projects!$A$14,"")&IF(Projects!$G$21="Yes",", "&Projects!$A$21,""),2)=", ",MID(IF(Projects!$G$14="Yes",Projects!$A$14,"")&IF(Projects!$G$21="Yes",", "&Projects!$A$21,""),3,1000),IF(Projects!$G$14="Yes",Projects!$A$14,"")&IF(Projects!$G$21="Yes",", "&Projects!$A$21,"")),"") -> 3rd St | AI6: =IF(Projects!$G$22="Yes",Projects!$A$22,"") | AL6: =IF(Projects!$G$23="Yes",Projects!$A$23,"") | AO6: =IF(Projects!$G$24="Yes",Projects!$A$24,"") | AR6: =IF(Projects!$G$25="Yes",Projects!$A$25,"") | AT6: =IF(Projects!$G$26="Yes",Projects!$A$26,"") | AV6: =IF(Projects!$G$27="Yes",Projects!$A$27,"") | AX6: =IF(Projects!$G$28="Yes",Projects!$A$28,"") | AZ6: =IF(Projects!$G$29="Yes",Projects!$A$29,"") | BB6: =IF(Projects!$G$30="Yes",Projects!$A$30,"") | BD6: =IF(Projects!$G$31="Yes",Projects!$A$31,"") | BF6: =IF(Projects!$G$32="Yes",Projects!$A$32,"") | BH6: =IF(Projects!$G$33="Yes",Projects!$A$33,"") | BJ6: =IF(Projects!$G$34="Yes",Projects!$A$34,"") | BL6: =IF(Projects!$G$35="Yes",Projects!$A$35,"") | BN6: =IF(Projects!$G$36="Yes",Projects!$A$36,"") | BP6: =IF(Projects!$G$37="Yes",Projects!$A$37,"") | BR6: =IF(Projects!$G$38="Yes",Projects!$A$38,"") | BT6: =IF(Projects!$G$39="Yes",Projects!$A$39,"") | BV6: =IF(Projects!$G$40="Yes",Projects!$A$40,"") | BX6: =IF(Projects!$G$41="Yes",Projects!$A$41,"") | BZ6: =IF(Projects!$G$42="Yes",Projects!$A$42,"") | CB6: =IF(Projects!$G$43="Yes",Projects!$A$43,"") | CD6: =IF(Projects!$G$44="Yes",Projects!$A$44,"") | CF6: =IF(Projects!$G$45="Yes",Projects!$A$45,"") | CH6: =IF(Projects!$G$46="Yes",Projects!$A$46,"")
A8: GC Revenue
