Workbook

Sheet Model
A1: Six Peak Capital - Financial Projections
B2: 46023 | C2: 46054 | D2: 46082 | E2: 46113 | F2: 46143 | G2: 46174 | H2: 46204 | I2: 46235 | J2: 46266 | K2: 46296 | L2: 46327 | M2: 46357 | N2: 46388 | O2: 46419 | P2: 46447 | Q2: 46478 | R2: 46508 | S2: 46539 | T2: 46569 | U2: 46600 | V2: 46631 | W2: 46661 | X2: 46692 | Y2: 46722 | Z2: 46753 | AA2: 46784 | AB2: 46813 | AC2: 46844 | AD2: 46874 | AE2: 46905 | AF2: 46935 | AG2: 46966 | AH2: 46997 | AI2: 47027 | AJ2: 47058 | AK2: 47088 | AL2: 47119 | AM2: 47150 | AN2: 47178 | AO2: 47209 | AP2: 47239 | AQ2: 47270 | AR2: 47300 | AS2: 47331 | AT2: 47362 | AU2: 47392 | AV2: 47423 | AW2: 47453 | AX2: 47484 | AY2: 47515 | AZ2: 47543 | BA2: 47574 | BB2: 47604 | BC2: 47635 | BD2: 47665 | BE2: 47696 | BF2: 47727 | BG2: 47757 | BH2: 47788 | BI2: 47818 | BJ2: 47849 | BK2: 47880 | BL2: 47908 | BM2: 47939 | BN2: 47969 | BO2: 48000 | BP2: 48030 | BQ2: 48061 | BR2: 48092 | BS2: 48122 | BT2: 48153 | BU2: 48183 | BV2: 48214 | BW2: 48245 | BX2: 48274 | BY2: 48305 | BZ2: 48335 | CA2: 48366 | CB2: 48396 | CC2: 48427 | CD2: 48458 | CE2: 48488 | CF2: 48519 | CG2: 48549 | CH2: 48580 | CI2: 48611 | CJ2: 48639 | CK2: 48670 | CL2: 48700 | CM2: 48731 | CN2: 48761 | CO2: 48792 | CP2: 48823 | CQ2: 48853 | CR2: 48884 | CS2: 48914 | CT2: 48945 | CU2: 48976 | CV2: 49004 | CW2: 49035 | CX2: 49065 | CY2: 49096 | CZ2: 49126 | DA2: 49157 | DB2: 49188 | DC2: 49218 | DD2: 49249 | DE2: 49279
A3: Month # | B3: -2 | C3: -1 | D3: 0 | E3: 1 | F3: 2 | G3: 3 | H3: 4 | I3: 5 | J3: 6 | K3: 7 | L3: 8 | M3: 9 | N3: 10 | O3: 11 | P3: 12 | Q3: 13 | R3: 14 | S3: 15 | T3: 16 | U3: 17 | V3: 18 | W3: 19 | X3: 20 | Y3: 21 | Z3: 22 | AA3: 23 | AB3: 24 | AC3: 25 | AD3: 26 | AE3: 27 | AF3: 28 | AG3: 29 | AH3: 30 | AI3: 31 | AJ3: 32 | AK3: 33 | AL3: 34 | AM3: 35 | AN3: 36 | AO3: 37 | AP3: 38 | AQ3: 39 | AR3: 40 | AS3: 41 | AT3: 42 | AU3: 43 | AV3: 44 | AW3: 45 | AX3: 46 | AY3: 47 | AZ3: 48 | BA3: 49 | BB3: 50 | BC3: 51 | BD3: 52 | BE3: 53 | BF3: 54 | BG3: 55 | BH3: 56 | BI3: 57 | BJ3: 58 | BK3: 59 | BL3: 60 | BM3: 61 | BN3: 62 | BO3: 63 | BP3: 64 | BQ3: 65 | BR3: 66 | BS3: 67 | BT3: 68 | BU3: 69 | BV3: 70 | BW3: 71 | BX3: 72 | BY3: 73 | BZ3: 74 | CA3: 75 | CB3: 76 | CC3: 77 | CD3: 78 | CE3: 79 | CF3: 80 | CG3: 81 | CH3: 82 | CI3: 83 | CJ3: 84 | CK3: 85 | CL3: 86 | CM3: 87 | CN3: 88 | CO3: 89 | CP3: 90 | CQ3: 91 | CR3: 92 | CS3: 93 | CT3: 94 | CU3: 95 | CV3: 96 | CW3: 97 | CX3: 98 | CY3: 99 | CZ3: 100 | DA3: 101 | DB3: 102 | DC3: 103 | DD3: 104 | DE3: 105
B4: =IF(ISBLANK(Actuals!C14),"","Actuals") -> Actuals | C4: =IF(ISBLANK(Actuals!D14),"","Actuals") -> Actuals | D4: =IF(ISBLANK(Actuals!E14),"","Actuals") -> Actuals | E4: =IF(ISBLANK(Actuals!F14),"","Actuals") -> Actuals | F4: =IF(ISBLANK(Actuals!G14),"","Actuals") -> Actuals | G4: =IF(ISBLANK(Actuals!H14),"","Actuals") -> Actuals | H4: =IF(ISBLANK(Actuals!I14),"","Actuals") | I4: =IF(ISBLANK(Actuals!J14),"","Actuals") | ... DE4: =IF(ISBLANK(Actuals!DF14),"","Actuals")
A5: YTD Actuals Snapshot:
E6: =MID(IF(AND(Projects!$G$2="Yes",Projects!$C$2=E$3),", "&Projects!$A$2,"")&IF(AND(Projects!$G$3="Yes",Projects!$C$3=E$3),", "&Projects!$A$3,"")&IF(AND(Projects!$G$4="Yes",Projects!$C$4=E$3),", "&Projects!$A$4,"")&IF(AND(Projects!$G$5="Yes",Projects!$C$5=E$3),", "&Projects!$A$5,"")&IF(AND(Projects!$G$6="Yes",Projects!$C$6=E$3),", "&Projects!$A$6,"")&IF(AND(Projects!$G$7="Yes",Projects!$C$7=E$3),", "&Projects!$A$7,"")&IF(AND(Projects!$G$8="Yes",Projects!$C$8=E$3),", "&Projects!$A$8,"")&IF(AND(Projects!$G$9="Yes",Projects!$C$9=E$3),", "&Projects!$A$9,"")&IF(AND(Projects!$G$10="Yes",Projects!$C$10=E$3),", "&Projects!$A$10,"")&IF(AND(Projects!$G$11="Yes",Projects!$C$11=E$3),", "&Projects!$A$11,"")&IF(AND(Projects!$G$12="Yes",Projects!$C$12=E$3),", "&Projects!$A$12,"")&IF(AND(Projects!$G$13="Yes",Projects!$C$13=E$3),", "&Projects!$A$13,"")&IF(AND(Projects!$G$14="Yes",Projects!$C$14=E$3),", "&Projects!$A$14,"")&IF(AND(Projects!$G$15="Yes",Projects!$C$15=E$3),", "&Projects!$A$15,"")&IF(AND(Projects!$G$16="Yes",Projects!$C$16=E$3),", "&Projects!$A$16,"")&IF(AND(Projects!$G$17="Yes",Projects!$C$17=E$3),", "&Projects!$A$17,"")&IF(AND(Projects!$G$18="Yes",Projects!$C$18=E$3),", "&Projects!$A$18,"")&IF(AND(Projects!$G$19="Yes",Projects!$C$19=E$3),", "&Projects!$A$19,"")&IF(AND(Projects!$G$20="Yes",Projects!$C$20=E$3),", "&Projects!$A$20,"")&IF(AND(Projects!$G$21="Yes",Projects!$C$21=E$3),", "&Projects!$A$21,"")&IF(AND(Projects!$G$22="Yes",Projects!$C$22=E$3),", "&Projects!$A$22,"")&IF(AND(Projects!$G$23="Yes",Projects!$C$23=E$3),", "&Projects!$A$23,"")&IF(AND(Projects!$G$24="Yes",Projects!$C$24=E$3),", "&Projects!$A$24,"")&IF(AND(Projects!$G$25="Yes",Projects!$C$25=E$3),", "&Projects!$A$25,"")&IF(AND(Projects!$G$26="Yes",Projects!$C$26=E$3),", "&Projects!$A$26,"")&IF(AND(Projects!$G$27="Yes",Projects!$C$27=E$3),", "&Projects!$A$27,"")&IF(AND(Projects!$G$28="Yes",Projects!$C$28=E$3),", "&Projects!$A$28,"")&IF(AND(Projects!$G$29="Yes",Projects!$C$29=E$3),", "&Projects!$A$29,"")&IF(AND(Projects!$G$30="Yes",Projects!$C$30=E$3),", "&Projects!$A$30,"")&IF(AND(Projects!$G$31="Yes",Projects!$C$31=E$3),", "&Projects!$A$31,"")&IF(AND(Projects!$G$32="Yes",Projects!$C$32=E$3),", "&Projects!$A$32,"")&IF(AND(Projects!$G$33="Yes",Projects!$C$33=E$3),", "&Projects!$A$33,"")&IF(AND(Projects!$G$34="Yes",Projects!$C$34=E$3),", "&Projects!$A$34,"")&IF(AND(Projects!$G$35="Yes",Projects!$C$35=E$3),", "&Projects!$A$35,"")&IF(AND(Projects!$G$36="Yes",Projects!$C$36=E$3),", "&Projects!$A$36,"")&IF(AND(Projects!$G$37="Yes",Projects!$C$37=E$3),", "&Projects!$A$37,"")&IF(AND(Projects!$G$38="Yes",Projects!$C$38=E$3),", "&Projects!$A$38,"")&IF(AND(Projects!$G$39="Yes",Projects!$C$39=E$3),", "&Projects!$A$39,"")&IF(AND(Projects!$G$40="Yes",Projects!$C$40=E$3),", "&Projects!$A$40,"")&IF(AND(Projects!$G$41="Yes",Projects!$C$41=E$3),", "&Projects!$A$41,"")&IF(AND(Projects!$G$42="Yes",Projects!$C$42=E$3),", "&Projects!$A$42,"")&IF(AND(Projects!$G$43="Yes",Projects!$C$43=E$3),", "&Projects!$A$43,"")&IF(AND(Projects!$G$44="Yes",Projects!$C$44=E$3),", "&Projects!$A$44,"")&IF(AND(Projects!$G$45="Yes",Projects!$C$45=E$3),", "&Projects!$A$45,"")&IF(AND(Projects!$G$46="Yes",Projects!$C$46=E$3),", "&Projects!$A$46,""),3,10000) -> Crenshaw, Ramsgate, Califa, Whipple, Nelrose | F6: =MID(IF(AND(Projects!$G$2="Yes",Projects!$C$2=F$3),", "&Projects!$A$2,"")&IF(AND(Projects!$G$3="Yes",Projects!$C$3=F$3),", "&Projects!$A$3,"")&IF(AND(Projects!$G$4="Yes",Projects!$C$4=F$3),", "&Projects!$A$4,"")&IF(AND(Projects!$G$5="Yes",Projects!$C$5=F$3),", "&Projects!$A$5,"")&IF(AND(Projects!$G$6="Yes",Projects!$C$6=F$3),", "&Projects!$A$6,"")&IF(AND(Projects!$G$7="Yes",Projects!$C$7=F$3),", "&Projects!$A$7,"")&IF(AND(Projects!$G$8="Yes",Projects!$C$8=F$3),", "&Projects!$A$8,"")&IF(AND(Projects!$G$9="Yes",Projects!$C$9=F$3),", "&Projects!$A$9,"")&IF(AND(Projects!$G$10="Yes",Projects!$C$10=F$3),", "&Projects!$A$10,"")&IF(AND(Projects!$G$11="Yes",Projects!$C$11=F$3),", "&Projects!$A$11,"")&IF(AND(Projects!$G$12="Yes",Projects!$C$12=F$3),", "&Projects!$A$12,"")&IF(AND(Projects!$G$13="Yes",Projects!$C$13=F$3),", "&Projects!$A$13,"")&IF(AND(Projects!$G$14="Yes",Projects!$C$14=F$3),", "&Projects!$A$14,"")&IF(AND(Projects!$G$15="Yes",Projects!$C$15=F$3),", "&Projects!$A$15,"")&IF(AND(Projects!$G$16="Yes",Projects!$C$16=F$3),", "&Projects!$A$16,"")&IF(AND(Projects!$G$17="Yes",Projects!$C$17=F$3),", "&Projects!$A$17,"")&IF(AND(Projects!$G$18="Yes",Projects!$C$18=F$3),", "&Projects!$A$18,"")&IF(AND(Projects!$G$19="Yes",Projects!$C$19=F$3),", "&Projects!$A$19,"")&IF(AND(Projects!$G$20="Yes",Projects!$C$20=F$3),", "&Projects!$A$20,"")&IF(AND(Projects!$G$21="Yes",Projects!$C$21=F$3),", "&Projects!$A$21,"")&IF(AND(Projects!$G$22="Yes",Projects!$C$22=F$3),", "&Projects!$A$22,"")&IF(AND(Projects!$G$23="Yes",Projects!$C$23=F$3),", "&Projects!$A$23,"")&IF(AND(Projects!$G$24="Yes",Projects!$C$24=F$3),", "&Projects!$A$24,"")&IF(AND(Projects!$G$25="Yes",Projects!$C$25=F$3),", "&Projects!$A$25,"")&IF(AND(Projects!$G$26="Yes",Projects!$C$26=F$3),", "&Projects!$A$26,"")&IF(AND(Projects!$G$27="Yes",Projects!$C$27=F$3),", "&Projects!$A$27,"")&IF(AND(Projects!$G$28="Yes",Projects!$C$28=F$3),", "&Projects!$A$28,"")&IF(AND(Projects!$G$29="Yes",Projects!$C$29=F$3),", "&Projects!$A$29,"")&IF(AND(Projects!$G$30="Yes",Projects!$C$30=F$3),", "&Projects!$A$30,"")&IF(AND(Projects!$G$31="Yes",Projects!$C$31=F$3),", "&Projects!$A$31,"")&IF(AND(Projects!$G$32="Yes",Projects!$C$32=F$3),", "&Projects!$A$32,"")&IF(AND(Projects!$G$33="Yes",Projects!$C$33=F$3),", "&Projects!$A$33,"")&IF(AND(Projects!$G$34="Yes",Projects!$C$34=F$3),", "&Projects!$A$34,"")&IF(AND(Projects!$G$35="Yes",Projects!$C$35=F$3),", "&Projects!$A$35,"")&IF(AND(Projects!$G$36="Yes",Projects!$C$36=F$3),", "&Projects!$A$36,"")&IF(AND(Projects!$G$37="Yes",Projects!$C$37=F$3),", "&Projects!$A$37,"")&IF(AND(Projects!$G$38="Yes",Projects!$C$38=F$3),", "&Projects!$A$38,"")&IF(AND(Projects!$G$39="Yes",Projects!$C$39=F$3),", "&Projects!$A$39,"")&IF(AND(Projects!$G$40="Yes",Projects!$C$40=F$3),", "&Projects!$A$40,"")&IF(AND(Projects!$G$41="Yes",Projects!$C$41=F$3),", "&Projects!$A$41,"")&IF(AND(Projects!$G$42="Yes",Projects!$C$42=F$3),", "&Projects!$A$42,"")&IF(AND(Projects!$G$43="Yes",Projects!$C$43=F$3),", "&Projects!$A$43,"")&IF(AND(Projects!$G$44="Yes",Projects!$C$44=F$3),", "&Projects!$A$44,"")&IF(AND(Projects!$G$45="Yes",Projects!$C$45=F$3),", "&Projects!$A$45,"")&IF(AND(Projects!$G$46="Yes",Projects!$C$46=F$3),", "&Projects!$A$46,""),3,10000) | G6: =MID(IF(AND(Projects!$G$2="Yes",Projects!$C$2=G$3),", "&Projects!$A$2,"")&IF(AND(Projects!$G$3="Yes",Projects!$C$3=G$3),", "&Projects!$A$3,"")&IF(AND(Projects!$G$4="Yes",Projects!$C$4=G$3),", "&Projects!$A$4,"")&IF(AND(Projects!$G$5="Yes",Projects!$C$5=G$3),", "&Projects!$A$5,"")&IF(AND(Projects!$G$6="Yes",Projects!$C$6=G$3),", "&Projects!$A$6,"")&IF(AND(Projects!$G$7="Yes",Projects!$C$7=G$3),", "&Projects!$A$7,"")&IF(AND(Projects!$G$8="Yes",Projects!$C$8=G$3),", "&Projects!$A$8,"")&IF(AND(Projects!$G$9="Yes",Projects!$C$9=G$3),", "&Projects!$A$9,"")&IF(AND(Projects!$G$10="Yes",Projects!$C$10=G$3),", "&Projects!$A$10,"")&IF(AND(Projects!$G$11="Yes",Projects!$C$11=G$3),", "&Projects!$A$11,"")&IF(AND(Projects!$G$12="Yes",Projects!$C$12=G$3),", "&Projects!$A$12,"")&IF(AND(Projects!$G$13="Yes",Projects!$C$13=G$3),", "&Projects!$A$13,"")&IF(AND(Projects!$G$14="Yes",Projects!$C$14=G$3),", "&Projects!$A$14,"")&IF(AND(Projects!$G$15="Yes",Projects!$C$15=G$3),", "&Projects!$A$15,"")&IF(AND(Projects!$G$16="Yes",Projects!$C$16=G$3),", "&Projects!$A$16,"")&IF(AND(Projects!$G$17="Yes",Projects!$C$17=G$3),", "&Projects!$A$17,"")&IF(AND(Projects!$G$18="Yes",Projects!$C$18=G$3),", "&Projects!$A$18,"")&IF(AND(Projects!$G$19="Yes",Projects!$C$19=G$3),", "&Projects!$A$19,"")&IF(AND(Projects!$G$20="Yes",Projects!$C$20=G$3),", "&Projects!$A$20,"")&IF(AND(Projects!$G$21="Yes",Projects!$C$21=G$3),", "&Projects!$A$21,"")&IF(AND(Projects!$G$22="Yes",Projects!$C$22=G$3),", "&Projects!$A$22,"")&IF(AND(Projects!$G$23="Yes",Projects!$C$23=G$3),", "&Projects!$A$23,"")&IF(AND(Projects!$G$24="Yes",Projects!$C$24=G$3),", "&Projects!$A$24,"")&IF(AND(Projects!$G$25="Yes",Projects!$C$25=G$3),", "&Projects!$A$25,"")&IF(AND(Projects!$G$26="Yes",Projects!$C$26=G$3),", "&Projects!$A$26,"")&IF(AND(Projects!$G$27="Yes",Projects!$C$27=G$3),", "&Projects!$A$27,"")&IF(AND(Projects!$G$28="Yes",Projects!$C$28=G$3),", "&Projects!$A$28,"")&IF(AND(Projects!$G$29="Yes",Projects!$C$29=G$3),", "&Projects!$A$29,"")&IF(AND(Projects!$G$30="Yes",Projects!$C$30=G$3),", "&Projects!$A$30,"")&IF(AND(Projects!$G$31="Yes",Projects!$C$31=G$3),", "&Projects!$A$31,"")&IF(AND(Projects!$G$32="Yes",Projects!$C$32=G$3),", "&Projects!$A$32,"")&IF(AND(Projects!$G$33="Yes",Projects!$C$33=G$3),", "&Projects!$A$33,"")&IF(AND(Projects!$G$34="Yes",Projects!$C$34=G$3),", "&Projects!$A$34,"")&IF(AND(Projects!$G$35="Yes",Projects!$C$35=G$3),", "&Projects!$A$35,"")&IF(AND(Projects!$G$36="Yes",Projects!$C$36=G$3),", "&Projects!$A$36,"")&IF(AND(Projects!$G$37="Yes",Projects!$C$37=G$3),", "&Projects!$A$37,"")&IF(AND(Projects!$G$38="Yes",Projects!$C$38=G$3),", "&Projects!$A$38,"")&IF(AND(Projects!$G$39="Yes",Projects!$C$39=G$3),", "&Projects!$A$39,"")&IF(AND(Projects!$G$40="Yes",Projects!$C$40=G$3),", "&Projects!$A$40,"")&IF(AND(Projects!$G$41="Yes",Projects!$C$41=G$3),", "&Projects!$A$41,"")&IF(AND(Projects!$G$42="Yes",Projects!$C$42=G$3),", "&Projects!$A$42,"")&IF(AND(Projects!$G$43="Yes",Projects!$C$43=G$3),", "&Projects!$A$43,"")&IF(AND(Projects!$G$44="Yes",Projects!$C$44=G$3),", "&Projects!$A$44,"")&IF(AND(Projects!$G$45="Yes",Projects!$C$45=G$3),", "&Projects!$A$45,"")&IF(AND(Projects!$G$46="Yes",Projects!$C$46=G$3),", "&Projects!$A$46,""),3,10000) | H6: =MID(IF(AND(Projects!$G$2="Yes",Projects!$C$2=H$3),", "&Projects!$A$2,"")&IF(AND(Projects!$G$3="Yes",Projects!$C$3=H$3),", "&Projects!$A$3,"")&IF(AND(Projects!$G$4="Yes",Projects!$C$4=H$3),", "&Projects!$A$4,"")&IF(AND(Projects!$G$5="Yes",Projects!$C$5=H$3),", "&Projects!$A$5,"")&IF(AND(Projects!$G$6="Yes",Projects!$C$6=H$3),", "&Projects!$A$6,"")&IF(AND(Projects!$G$7="Yes",Projects!$C$7=H$3),", "&Projects!$A$7,"")&IF(AND(Projects!$G$8="Yes",Projects!$C$8=H$3),", "&Projects!$A$8,"")&IF(AND(Projects!$G$9="Yes",Projects!$C$9=H$3),", "&Projects!$A$9,"")&IF(AND(Projects!$G$10="Yes",Projects!$C$10=H$3),", "&Projects!$A$10,"")&IF(AND(Projects!$G$11="Yes",Projects!$C$11=H$3),", "&Projects!$A$11,"")&IF(AND(Projects!$G$12="Yes",Projects!$C$12=H$3),", "&Projects!$A$12,"")&IF(AND(Projects!$G$13="Yes",Projects!$C$13=H$3),", "&Projects!$A$13,"")&IF(AND(Projects!$G$14="Yes",Projects!$C$14=H$3),", "&Projects!$A$14,"")&IF(AND(Projects!$G$15="Yes",Projects!$C$15=H$3),", "&Projects!$A$15,"")&IF(AND(Projects!$G$16="Yes",Projects!$C$16=H$3),", "&Projects!$A$16,"")&IF(AND(Projects!$G$17="Yes",Projects!$C$17=H$3),", "&Projects!$A$17,"")&IF(AND(Projects!$G$18="Yes",Projects!$C$18=H$3),", "&Projects!$A$18,"")&IF(AND(Projects!$G$19="Yes",Projects!$C$19=H$3),", "&Projects!$A$19,"")&IF(AND(Projects!$G$20="Yes",Projects!$C$20=H$3),", "&Projects!$A$20,"")&IF(AND(Projects!$G$21="Yes",Projects!$C$21=H$3),", "&Projects!$A$21,"")&IF(AND(Projects!$G$22="Yes",Projects!$C$22=H$3),", "&Projects!$A$22,"")&IF(AND(Projects!$G$23="Yes",Projects!$C$23=H$3),", "&Projects!$A$23,"")&IF(AND(Projects!$G$24="Yes",Projects!$C$24=H$3),", "&Projects!$A$24,"")&IF(AND(Projects!$G$25="Yes",Projects!$C$25=H$3),", "&Projects!$A$25,"")&IF(AND(Projects!$G$26="Yes",Projects!$C$26=H$3),", "&Projects!$A$26,"")&IF(AND(Projects!$G$27="Yes",Projects!$C$27=H$3),", "&Projects!$A$27,"")&IF(AND(Projects!$G$28="Yes",Projects!$C$28=H$3),", "&Projects!$A$28,"")&IF(AND(Projects!$G$29="Yes",Projects!$C$29=H$3),", "&Projects!$A$29,"")&IF(AND(Projects!$G$30="Yes",Projects!$C$30=H$3),", "&Projects!$A$30,"")&IF(AND(Projects!$G$31="Yes",Projects!$C$31=H$3),", "&Projects!$A$31,"")&IF(AND(Projects!$G$32="Yes",Projects!$C$32=H$3),", "&Projects!$A$32,"")&IF(AND(Projects!$G$33="Yes",Projects!$C$33=H$3),", "&Projects!$A$33,"")&IF(AND(Projects!$G$34="Yes",Projects!$C$34=H$3),", "&Projects!$A$34,"")&IF(AND(Projects!$G$35="Yes",Projects!$C$35=H$3),", "&Projects!$A$35,"")&IF(AND(Projects!$G$36="Yes",Projects!$C$36=H$3),", "&Projects!$A$36,"")&IF(AND(Projects!$G$37="Yes",Projects!$C$37=H$3),", "&Projects!$A$37,"")&IF(AND(Projects!$G$38="Yes",Projects!$C$38=H$3),", "&Projects!$A$38,"")&IF(AND(Projects!$G$39="Yes",Projects!$C$39=H$3),", "&Projects!$A$39,"")&IF(AND(Projects!$G$40="Yes",Projects!$C$40=H$3),", "&Projects!$A$40,"")&IF(AND(Projects!$G$41="Yes",Projects!$C$41=H$3),", "&Projects!$A$41,"")&IF(AND(Projects!$G$42="Yes",Projects!$C$42=H$3),", "&Projects!$A$42,"")&IF(AND(Projects!$G$43="Yes",Projects!$C$43=H$3),", "&Projects!$A$43,"")&IF(AND(Projects!$G$44="Yes",Projects!$C$44=H$3),", "&Projects!$A$44,"")&IF(AND(Projects!$G$45="Yes",Projects!$C$45=H$3),", "&Projects!$A$45,"")&IF(AND(Projects!$G$46="Yes",Projects!$C$46=H$3),", "&Projects!$A$46,""),3,10000) | I6: =MID(IF(AND(Projects!$G$2="Yes",Projects!$C$2=I$3),", "&Projects!$A$2,"")&IF(AND(Projects!$G$3="Yes",Projects!$C$3=I$3),", "&Projects!$A$3,"")&IF(AND(Projects!$G$4="Yes",Projects!$C$4=I$3),", "&Projects!$A$4,"")&IF(AND(Projects!$G$5="Yes",Projects!$C$5=I$3),", "&Projects!$A$5,"")&IF(AND(Projects!$G$6="Yes",Projects!$C$6=I$3),", "&Projects!$A$6,"")&IF(AND(Projects!$G$7="Yes",Projects!$C$7=I$3),", "&Projects!$A$7,"")&IF(AND(Projects!$G$8="Yes",Projects!$C$8=I$3),", "&Projects!$A$8,"")&IF(AND(Projects!$G$9="Yes",Projects!$C$9=I$3),", "&Projects!$A$9,"")&IF(AND(Projects!$G$10="Yes",Projects!$C$10=I$3),", "&Projects!$A$10,"")&IF(AND(Projects!$G$11="Yes",Projects!$C$11=I$3),", "&Projects!$A$11,"")&IF(AND(Projects!$G$12="Yes",Projects!$C$12=I$3),", "&Projects!$A$12,"")&IF(AND(Projects!$G$13="Yes",Projects!$C$13=I$3),", "&Projects!$A$13,"")&IF(AND(Projects!$G$14="Yes",Projects!$C$14=I$3),", "&Projects!$A$14,"")&IF(AND(Projects!$G$15="Yes",Projects!$C$15=I$3),", "&Projects!$A$15,"")&IF(AND(Projects!$G$16="Yes",Projects!$C$16=I$3),", "&Projects!$A$16,"")&IF(AND(Projects!$G$17="Yes",Projects!$C$17=I$3),", "&Projects!$A$17,"")&IF(AND(Projects!$G$18="Yes",Projects!$C$18=I$3),", "&Projects!$A$18,"")&IF(AND(Projects!$G$19="Yes",Projects!$C$19=I$3),", "&Projects!$A$19,"")&IF(AND(Projects!$G$20="Yes",Projects!$C$20=I$3),", "&Projects!$A$20,"")&IF(AND(Projects!$G$21="Yes",Projects!$C$21=I$3),", "&Projects!$A$21,"")&IF(AND(Projects!$G$22="Yes",Projects!$C$22=I$3),", "&Projects!$A$22,"")&IF(AND(Projects!$G$23="Yes",Projects!$C$23=I$3),", "&Projects!$A$23,"")&IF(AND(Projects!$G$24="Yes",Projects!$C$24=I$3),", "&Projects!$A$24,"")&IF(AND(Projects!$G$25="Yes",Projects!$C$25=I$3),", "&Projects!$A$25,"")&IF(AND(Projects!$G$26="Yes",Projects!$C$26=I$3),", "&Projects!$A$26,"")&IF(AND(Projects!$G$27="Yes",Projects!$C$27=I$3),", "&Projects!$A$27,"")&IF(AND(Projects!$G$28="Yes",Projects!$C$28=I$3),", "&Projects!$A$28,"")&IF(AND(Projects!$G$29="Yes",Projects!$C$29=I$3),", "&Projects!$A$29,"")&IF(AND(Projects!$G$30="Yes",Projects!$C$30=I$3),", "&Projects!$A$30,"")&IF(AND(Projects!$G$31="Yes",Projects!$C$31=I$3),", "&Projects!$A$31,"")&IF(AND(Projects!$G$32="Yes",Projects!$C$32=I$3),", "&Projects!$A$32,"")&IF(AND(Projects!$G$33="Yes",Projects!$C$33=I$3),", "&Projects!$A$33,"")&IF(AND(Projects!$G$34="Yes",Projects!$C$34=I$3),", "&Projects!$A$34,"")&IF(AND(Projects!$G$35="Yes",Projects!$C$35=I$3),", "&Projects!$A$35,"")&IF(AND(Projects!$G$36="Yes",Projects!$C$36=I$3),", "&Projects!$A$36,"")&IF(AND(Projects!$G$37="Yes",Projects!$C$37=I$3),", "&Projects!$A$37,"")&IF(AND(Projects!$G$38="Yes",Projects!$C$38=I$3),", "&Projects!$A$38,"")&IF(AND(Projects!$G$39="Yes",Projects!$C$39=I$3),", "&Projects!$A$39,"")&IF(AND(Projects!$G$40="Yes",Projects!$C$40=I$3),", "&Projects!$A$40,"")&IF(AND(Projects!$G$41="Yes",Projects!$C$41=I$3),", "&Projects!$A$41,"")&IF(AND(Projects!$G$42="Yes",Projects!$C$42=I$3),", "&Projects!$A$42,"")&IF(AND(Projects!$G$43="Yes",Projects!$C$43=I$3),", "&Projects!$A$43,"")&IF(AND(Projects!$G$44="Yes",Projects!$C$44=I$3),", "&Projects!$A$44,"")&IF(AND(Projects!$G$45="Yes",Projects!$C$45=I$3),", "&Projects!$A$45,"")&IF(AND(Projects!$G$46="Yes",Projects!$C$46=I$3),", "&Projects!$A$46,""),3,10000) -> Francis, Lexington, Denny | J6: =MID(IF(AND(Projects!$G$2="Yes",Projects!$C$2=J$3),", "&Projects!$A$2,"")&IF(AND(Projects!$G$3="Yes",Projects!$C$3=J$3),", "&Projects!$A$3,"")&IF(AND(Projects!$G$4="Yes",Projects!$C$4=J$3),", "&Projects!$A$4,"")&IF(AND(Projects!$G$5="Yes",Projects!$C$5=J$3),", "&Projects!$A$5,"")&IF(AND(Projects!$G$6="Yes",Projects!$C$6=J$3),", "&Projects!$A$6,"")&IF(AND(Projects!$G$7="Yes",Projects!$C$7=J$3),", "&Projects!$A$7,"")&IF(AND(Projects!$G$8="Yes",Projects!$C$8=J$3),", "&Projects!$A$8,"")&IF(AND(Projects!$G$9="Yes",Projects!$C$9=J$3),", "&Projects!$A$9,"")&IF(AND(Projects!$G$10="Yes",Projects!$C$10=J$3),", "&Projects!$A$10,"")&IF(AND(Projects!$G$11="Yes",Projects!$C$11=J$3),", "&Projects!$A$11,"")&IF(AND(Projects!$G$12="Yes",Projects!$C$12=J$3),", "&Projects!$A$12,"")&IF(AND(Projects!$G$13="Yes",Projects!$C$13=J$3),", "&Projects!$A$13,"")&IF(AND(Projects!$G$14="Yes",Projects!$C$14=J$3),", "&Projects!$A$14,"")&IF(AND(Projects!$G$15="Yes",Projects!$C$15=J$3),", "&Projects!$A$15,"")&IF(AND(Projects!$G$16="Yes",Projects!$C$16=J$3),", "&Projects!$A$16,"")&IF(AND(Projects!$G$17="Yes",Projects!$C$17=J$3),", "&Projects!$A$17,"")&IF(AND(Projects!$G$18="Yes",Projects!$C$18=J$3),", "&Projects!$A$18,"")&IF(AND(Projects!$G$19="Yes",Projects!$C$19=J$3),", "&Projects!$A$19,"")&IF(AND(Projects!$G$20="Yes",Projects!$C$20=J$3),", "&Projects!$A$20,"")&IF(AND(Projects!$G$21="Yes",Projects!$C$21=J$3),", "&Projects!$A$21,"")&IF(AND(Projects!$G$22="Yes",Projects!$C$22=J$3),", "&Projects!$A$22,"")&IF(AND(Projects!$G$23="Yes",Projects!$C$23=J$3),", "&Projects!$A$23,"")&IF(AND(Projects!$G$24="Yes",Projects!$C$24=J$3),", "&Projects!$A$24,"")&IF(AND(Projects!$G$25="Yes",Projects!$C$25=J$3),", "&Projects!$A$25,"")&IF(AND(Projects!$G$26="Yes",Projects!$C$26=J$3),", "&Projects!$A$26,"")&IF(AND(Projects!$G$27="Yes",Projects!$C$27=J$3),", "&Projects!$A$27,"")&IF(AND(Projects!$G$28="Yes",Projects!$C$28=J$3),", "&Projects!$A$28,"")&IF(AND(Projects!$G$29="Yes",Projects!$C$29=J$3),", "&Projects!$A$29,"")&IF(AND(Projects!$G$30="Yes",Projects!$C$30=J$3),", "&Projects!$A$30,"")&IF(AND(Projects!$G$31="Yes",Projects!$C$31=J$3),", "&Projects!$A$31,"")&IF(AND(Projects!$G$32="Yes",Projects!$C$32=J$3),", "&Projects!$A$32,"")&IF(AND(Projects!$G$33="Yes",Projects!$C$33=J$3),", "&Projects!$A$33,"")&IF(AND(Projects!$G$34="Yes",Projects!$C$34=J$3),", "&Projects!$A$34,"")&IF(AND(Projects!$G$35="Yes",Projects!$C$35=J$3),", "&Projects!$A$35,"")&IF(AND(Projects!$G$36="Yes",Projects!$C$36=J$3),", "&Projects!$A$36,"")&IF(AND(Projects!$G$37="Yes",Projects!$C$37=J$3),", "&Projects!$A$37,"")&IF(AND(Projects!$G$38="Yes",Projects!$C$38=J$3),", "&Projects!$A$38,"")&IF(AND(Projects!$G$39="Yes",Projects!$C$39=J$3),", "&Projects!$A$39,"")&IF(AND(Projects!$G$40="Yes",Projects!$C$40=J$3),", "&Projects!$A$40,"")&IF(AND(Projects!$G$41="Yes",Projects!$C$41=J$3),", "&Projects!$A$41,"")&IF(AND(Projects!$G$42="Yes",Projects!$C$42=J$3),", "&Projects!$A$42,"")&IF(AND(Projects!$G$43="Yes",Projects!$C$43=J$3),", "&Projects!$A$43,"")&IF(AND(Projects!$G$44="Yes",Projects!$C$44=J$3),", "&Projects!$A$44,"")&IF(AND(Projects!$G$45="Yes",Projects!$C$45=J$3),", "&Projects!$A$45,"")&IF(AND(Projects!$G$46="Yes",Projects!$C$46=J$3),", "&Projects!$A$46,""),3,10000) | K6: =MID(IF(AND(Projects!$G$2="Yes",Projects!$C$2=K$3),", "&Projects!$A$2,"")&IF(AND(Projects!$G$3="Yes",Projects!$C$3=K$3),", "&Projects!$A$3,"")&IF(AND(Projects!$G$4="Yes",Projects!$C$4=K$3),", "&Projects!$A$4,"")&IF(AND(Projects!$G$5="Yes",Projects!$C$5=K$3),", "&Projects!$A$5,"")&IF(AND(Projects!$G$6="Yes",Projects!$C$6=K$3),", "&Projects!$A$6,"")&IF(AND(Projects!$G$7="Yes",Projects!$C$7=K$3),", "&Projects!$A$7,"")&IF(AND(Projects!$G$8="Yes",Projects!$C$8=K$3),", "&Projects!$A$8,"")&IF(AND(Projects!$G$9="Yes",Projects!$C$9=K$3),", "&Projects!$A$9,"")&IF(AND(Projects!$G$10="Yes",Projects!$C$10=K$3),", "&Projects!$A$10,"")&IF(AND(Projects!$G$11="Yes",Projects!$C$11=K$3),", "&Projects!$A$11,"")&IF(AND(Projects!$G$12="Yes",Projects!$C$12=K$3),", "&Projects!$A$12,"")&IF(AND(Projects!$G$13="Yes",Projects!$C$13=K$3),", "&Projects!$A$13,"")&IF(AND(Projects!$G$14="Yes",Projects!$C$14=K$3),", "&Projects!$A$14,"")&IF(AND(Projects!$G$15="Yes",Projects!$C$15=K$3),", "&Projects!$A$15,"")&IF(AND(Projects!$G$16="Yes",Projects!$C$16=K$3),", "&Projects!$A$16,"")&IF(AND(Projects!$G$17="Yes",Projects!$C$17=K$3),", "&Projects!$A$17,"")&IF(AND(Projects!$G$18="Yes",Projects!$C$18=K$3),", "&Projects!$A$18,"")&IF(AND(Projects!$G$19="Yes",Projects!$C$19=K$3),", "&Projects!$A$19,"")&IF(AND(Projects!$G$20="Yes",Projects!$C$20=K$3),", "&Projects!$A$20,"")&IF(AND(Projects!$G$21="Yes",Projects!$C$21=K$3),", "&Projects!$A$21,"")&IF(AND(Projects!$G$22="Yes",Projects!$C$22=K$3),", "&Projects!$A$22,"")&IF(AND(Projects!$G$23="Yes",Projects!$C$23=K$3),", "&Projects!$A$23,"")&IF(AND(Projects!$G$24="Yes",Projects!$C$24=K$3),", "&Projects!$A$24,"")&IF(AND(Projects!$G$25="Yes",Projects!$C$25=K$3),", "&Projects!$A$25,"")&IF(AND(Projects!$G$26="Yes",Projects!$C$26=K$3),", "&Projects!$A$26,"")&IF(AND(Projects!$G$27="Yes",Projects!$C$27=K$3),", "&Projects!$A$27,"")&IF(AND(Projects!$G$28="Yes",Projects!$C$28=K$3),", "&Projects!$A$28,"")&IF(AND(Projects!$G$29="Yes",Projects!$C$29=K$3),", "&Projects!$A$29,"")&IF(AND(Projects!$G$30="Yes",Projects!$C$30=K$3),", "&Projects!$A$30,"")&IF(AND(Projects!$G$31="Yes",Projects!$C$31=K$3),", "&Projects!$A$31,"")&IF(AND(Projects!$G$32="Yes",Projects!$C$32=K$3),", "&Projects!$A$32,"")&IF(AND(Projects!$G$33="Yes",Projects!$C$33=K$3),", "&Projects!$A$33,"")&IF(AND(Projects!$G$34="Yes",Projects!$C$34=K$3),", "&Projects!$A$34,"")&IF(AND(Projects!$G$35="Yes",Projects!$C$35=K$3),", "&Projects!$A$35,"")&IF(AND(Projects!$G$36="Yes",Projects!$C$36=K$3),", "&Projects!$A$36,"")&IF(AND(Projects!$G$37="Yes",Projects!$C$37=K$3),", "&Projects!$A$37,"")&IF(AND(Projects!$G$38="Yes",Projects!$C$38=K$3),", "&Projects!$A$38,"")&IF(AND(Projects!$G$39="Yes",Projects!$C$39=K$3),", "&Projects!$A$39,"")&IF(AND(Projects!$G$40="Yes",Projects!$C$40=K$3),", "&Projects!$A$40,"")&IF(AND(Projects!$G$41="Yes",Projects!$C$41=K$3),", "&Projects!$A$41,"")&IF(AND(Projects!$G$42="Yes",Projects!$C$42=K$3),", "&Projects!$A$42,"")&IF(AND(Projects!$G$43="Yes",Projects!$C$43=K$3),", "&Projects!$A$43,"")&IF(AND(Projects!$G$44="Yes",Projects!$C$44=K$3),", "&Projects!$A$44,"")&IF(AND(Projects!$G$45="Yes",Projects!$C$45=K$3),", "&Projects!$A$45,"")&IF(AND(Projects!$G$46="Yes",Projects!$C$46=K$3),", "&Projects!$A$46,""),3,10000) | L6: =MID(IF(AND(Projects!$G$2="Yes",Projects!$C$2=L$3),", "&Projects!$A$2,"")&IF(AND(Projects!$G$3="Yes",Projects!$C$3=L$3),", "&Projects!$A$3,"")&IF(AND(Projects!$G$4="Yes",Projects!$C$4=L$3),", "&Projects!$A$4,"")&IF(AND(Projects!$G$5="Yes",Projects!$C$5=L$3),", "&Projects!$A$5,"")&IF(AND(Projects!$G$6="Yes",Projects!$C$6=L$3),", "&Projects!$A$6,"")&IF(AND(Projects!$G$7="Yes",Projects!$C$7=L$3),", "&Projects!$A$7,"")&IF(AND(Projects!$G$8="Yes",Projects!$C$8=L$3),", "&Projects!$A$8,"")&IF(AND(Projects!$G$9="Yes",Projects!$C$9=L$3),", "&Projects!$A$9,"")&IF(AND(Projects!$G$10="Yes",Projects!$C$10=L$3),", "&Projects!$A$10,"")&IF(AND(Projects!$G$11="Yes",Projects!$C$11=L$3),", "&Projects!$A$11,"")&IF(AND(Projects!$G$12="Yes",Projects!$C$12=L$3),", "&Projects!$A$12,"")&IF(AND(Projects!$G$13="Yes",Projects!$C$13=L$3),", "&Projects!$A$13,"")&IF(AND(Projects!$G$14="Yes",Projects!$C$14=L$3),", "&Projects!$A$14,"")&IF(AND(Projects!$G$15="Yes",Projects!$C$15=L$3),", "&Projects!$A$15,"")&IF(AND(Projects!$G$16="Yes",Projects!$C$16=L$3),", "&Projects!$A$16,"")&IF(AND(Projects!$G$17="Yes",Projects!$C$17=L$3),", "&Projects!$A$17,"")&IF(AND(Projects!$G$18="Yes",Projects!$C$18=L$3),", "&Projects!$A$18,"")&IF(AND(Projects!$G$19="Yes",Projects!$C$19=L$3),", "&Projects!$A$19,"")&IF(AND(Projects!$G$20="Yes",Projects!$C$20=L$3),", "&Projects!$A$20,"")&IF(AND(Projects!$G$21="Yes",Projects!$C$21=L$3),", "&Projects!$A$21,"")&IF(AND(Projects!$G$22="Yes",Projects!$C$22=L$3),", "&Projects!$A$22,"")&IF(AND(Projects!$G$23="Yes",Projects!$C$23=L$3),", "&Projects!$A$23,"")&IF(AND(Projects!$G$24="Yes",Projects!$C$24=L$3),", "&Projects!$A$24,"")&IF(AND(Projects!$G$25="Yes",Projects!$C$25=L$3),", "&Projects!$A$25,"")&IF(AND(Projects!$G$26="Yes",Projects!$C$26=L$3),", "&Projects!$A$26,"")&IF(AND(Projects!$G$27="Yes",Projects!$C$27=L$3),", "&Projects!$A$27,"")&IF(AND(Projects!$G$28="Yes",Projects!$C$28=L$3),", "&Projects!$A$28,"")&IF(AND(Projects!$G$29="Yes",Projects!$C$29=L$3),", "&Projects!$A$29,"")&IF(AND(Projects!$G$30="Yes",Projects!$C$30=L$3),", "&Projects!$A$30,"")&IF(AND(Projects!$G$31="Yes",Projects!$C$31=L$3),", "&Projects!$A$31,"")&IF(AND(Projects!$G$32="Yes",Projects!$C$32=L$3),", "&Projects!$A$32,"")&IF(AND(Projects!$G$33="Yes",Projects!$C$33=L$3),", "&Projects!$A$33,"")&IF(AND(Projects!$G$34="Yes",Projects!$C$34=L$3),", "&Projects!$A$34,"")&IF(AND(Projects!$G$35="Yes",Projects!$C$35=L$3),", "&Projects!$A$35,"")&IF(AND(Projects!$G$36="Yes",Projects!$C$36=L$3),", "&Projects!$A$36,"")&IF(AND(Projects!$G$37="Yes",Projects!$C$37=L$3),", "&Projects!$A$37,"")&IF(AND(Projects!$G$38="Yes",Projects!$C$38=L$3),", "&Projects!$A$38,"")&IF(AND(Projects!$G$39="Yes",Projects!$C$39=L$3),", "&Projects!$A$39,"")&IF(AND(Projects!$G$40="Yes",Projects!$C$40=L$3),", "&Projects!$A$40,"")&IF(AND(Projects!$G$41="Yes",Projects!$C$41=L$3),", "&Projects!$A$41,"")&IF(AND(Projects!$G$42="Yes",Projects!$C$42=L$3),", "&Projects!$A$42,"")&IF(AND(Projects!$G$43="Yes",Projects!$C$43=L$3),", "&Projects!$A$43,"")&IF(AND(Projects!$G$44="Yes",Projects!$C$44=L$3),", "&Projects!$A$44,"")&IF(AND(Projects!$G$45="Yes",Projects!$C$45=L$3),", "&Projects!$A$45,"")&IF(AND(Projects!$G$46="Yes",Projects!$C$46=L$3),", "&Projects!$A$46,""),3,10000) -> Acama | ... DE6: =MID(IF(AND(Projects!$G$2="Yes",Projects!$C$2=DE$3),", "&Projects!$A$2,"")&IF(AND(Projects!$G$3="Yes",Projects!$C$3=DE$3),", "&Projects!$A$3,"")&IF(AND(Projects!$G$4="Yes",Projects!$C$4=DE$3),", "&Projects!$A$4,"")&IF(AND(Projects!$G$5="Yes",Projects!$C$5=DE$3),", "&Projects!$A$5,"")&IF(AND(Projects!$G$6="Yes",Projects!$C$6=DE$3),", "&Projects!$A$6,"")&IF(AND(Projects!$G$7="Yes",Projects!$C$7=DE$3),", "&Projects!$A$7,"")&IF(AND(Projects!$G$8="Yes",Projects!$C$8=DE$3),", "&Projects!$A$8,"")&IF(AND(Projects!$G$9="Yes",Projects!$C$9=DE$3),", "&Projects!$A$9,"")&IF(AND(Projects!$G$10="Yes",Projects!$C$10=DE$3),", "&Projects!$A$10,"")&IF(AND(Projects!$G$11="Yes",Projects!$C$11=DE$3),", "&Projects!$A$11,"")&IF(AND(Projects!$G$12="Yes",Projects!$C$12=DE$3),", "&Projects!$A$12,"")&IF(AND(Projects!$G$13="Yes",Projects!$C$13=DE$3),", "&Projects!$A$13,"")&IF(AND(Projects!$G$14="Yes",Projects!$C$14=DE$3),", "&Projects!$A$14,"")&IF(AND(Projects!$G$15="Yes",Projects!$C$15=DE$3),", "&Projects!$A$15,"")&IF(AND(Projects!$G$16="Yes",Projects!$C$16=DE$3),", "&Projects!$A$16,"")&IF(AND(Projects!$G$17="Yes",Projects!$C$17=DE$3),", "&Projects!$A$17,"")&IF(AND(Projects!$G$18="Yes",Projects!$C$18=DE$3),", "&Projects!$A$18,"")&IF(AND(Projects!$G$19="Yes",Projects!$C$19=DE$3),", "&Projects!$A$19,"")&IF(AND(Projects!$G$20="Yes",Projects!$C$20=DE$3),", "&Projects!$A$20,"")&IF(AND(Projects!$G$21="Yes",Projects!$C$21=DE$3),", "&Projects!$A$21,"")&IF(AND(Projects!$G$22="Yes",Projects!$C$22=DE$3),", "&Projects!$A$22,"")&IF(AND(Projects!$G$23="Yes",Projects!$C$23=DE$3),", "&Projects!$A$23,"")&IF(AND(Projects!$G$24="Yes",Projects!$C$24=DE$3),", "&Projects!$A$24,"")&IF(AND(Projects!$G$25="Yes",Projects!$C$25=DE$3),", "&Projects!$A$25,"")&IF(AND(Projects!$G$26="Yes",Projects!$C$26=DE$3),", "&Projects!$A$26,"")&IF(AND(Projects!$G$27="Yes",Projects!$C$27=DE$3),", "&Projects!$A$27,"")&IF(AND(Projects!$G$28="Yes",Projects!$C$28=DE$3),", "&Projects!$A$28,"")&IF(AND(Projects!$G$29="Yes",Projects!$C$29=DE$3),", "&Projects!$A$29,"")&IF(AND(Projects!$G$30="Yes",Projects!$C$30=DE$3),", "&Projects!$A$30,"")&IF(AND(Projects!$G$31="Yes",Projects!$C$31=DE$3),", "&Projects!$A$31,"")&IF(AND(Projects!$G$32="Yes",Projects!$C$32=DE$3),", "&Projects!$A$32,"")&IF(AND(Projects!$G$33="Yes",Projects!$C$33=DE$3),", "&Projects!$A$33,"")&IF(AND(Projects!$G$34="Yes",Projects!$C$34=DE$3),", "&Projects!$A$34,"")&IF(AND(Projects!$G$35="Yes",Projects!$C$35=DE$3),", "&Projects!$A$35,"")&IF(AND(Projects!$G$36="Yes",Projects!$C$36=DE$3),", "&Projects!$A$36,"")&IF(AND(Projects!$G$37="Yes",Projects!$C$37=DE$3),", "&Projects!$A$37,"")&IF(AND(Projects!$G$38="Yes",Projects!$C$38=DE$3),", "&Projects!$A$38,"")&IF(AND(Projects!$G$39="Yes",Projects!$C$39=DE$3),", "&Projects!$A$39,"")&IF(AND(Projects!$G$40="Yes",Projects!$C$40=DE$3),", "&Projects!$A$40,"")&IF(AND(Projects!$G$41="Yes",Projects!$C$41=DE$3),", "&Projects!$A$41,"")&IF(AND(Projects!$G$42="Yes",Projects!$C$42=DE$3),", "&Projects!$A$42,"")&IF(AND(Projects!$G$43="Yes",Projects!$C$43=DE$3),", "&Projects!$A$43,"")&IF(AND(Projects!$G$44="Yes",Projects!$C$44=DE$3),", "&Projects!$A$44,"")&IF(AND(Projects!$G$45="Yes",Projects!$C$45=DE$3),", "&Projects!$A$45,"")&IF(AND(Projects!$G$46="Yes",Projects!$C$46=DE$3),", "&Projects!$A$46,""),3,10000)
A8: GC Revenue
