Workbook

Sheet Consolidated
A1: Six Peak consolidated FY2027 budget
A2: Recommended for board approval, 2 November 2026 (internal sign-off 26 Oct; revised 28 Oct). LV + Six Peak + APA (Six Peak's 50% share). Key assumptions are on the next tab; line detail on the LV, Six Peak and APA tabs.
A4: $ | B4: Jan-27 | C4: Feb-27 | D4: Mar-27 | E4: Apr-27 | F4: May-27 | G4: Jun-27 | H4: Jul-27 | I4: Aug-27 | J4: Sep-27 | K4: Oct-27 | L4: Nov-27 | M4: Dec-27 | N4: FY2027
A5: NET REVENUE
A6: LV fee income (supervision, project admin, GC fee) | B6: =LV!B6+LV!B7 -> 729468.99 | C6: =LV!C6+LV!C7 -> 748142.85 | D6: =LV!D6+LV!D7 -> 777487.75 | E6: =LV!E6+LV!E7 -> 860953.4 | F6: =LV!F6+LV!F7 -> 905139.33 | G6: =LV!G6+LV!G7 -> 1191181.6 | H6: =LV!H6+LV!H7 -> 1284896.6 | I6: =LV!I6+LV!I7 -> 1175156.2 | ... M6: =LV!M6+LV!M7 -> 1280719 | N6: =SUM(B6:M6) -> 13046187
A7: LV trade margin, net (trade billing less trade cost, after true-ups) | B7: =LV!B26+LV!B46+LV!B49+LV!B50 -> -72850.08 | C7: =LV!C26+LV!C46+LV!C49+LV!C50 -> -62262.93 | D7: =LV!D26+LV!D46+LV!D49+LV!D50 -> -73133.21 | E7: =LV!E26+LV!E46+LV!E49+LV!E50 -> -62812.56 | F7: =LV!F26+LV!F46+LV!F49+LV!F50 -> -50942.25 | G7: =LV!G26+LV!G46+LV!G49+LV!G50 -> -51188.3 | H7: =LV!H26+LV!H46+LV!H49+LV!H50 -> -61690.61 | I7: =LV!I26+LV!I46+LV!I49+LV!I50 -> -55652.22 | ... M7: =LV!M26+LV!M46+LV!M49+LV!M50 -> 0 | N7: =SUM(B7:M7) -> -514774.95
A8: LV bonding program, net (bond line less Krueger fee and CBI premium) | B8: =LV!B48 -> 0 | C8: =LV!C48 -> 0 | D8: =LV!D48 -> 0 | E8: =LV!E48 -> -332539.87 | F8: =LV!F48 -> -204464.98 | G8: =LV!G48 -> -583586.3 | H8: =LV!H48 -> 0 | I8: =LV!I48 -> 0 | ... M8: =LV!M48 -> 0 | N8: =SUM(B8:M8) -> -1615478.6
A9: Six Peak developer fees | B9: ='Six Peak'!B11 -> 35864.145 | C9: ='Six Peak'!C11 -> 39022.039 | D9: ='Six Peak'!D11 -> 39022.039 | E9: ='Six Peak'!E11 -> 39022.039 | F9: ='Six Peak'!F11 -> 39022.039 | G9: ='Six Peak'!G11 -> 39022.039 | H9: ='Six Peak'!H11 -> 15115.789 | I9: ='Six Peak'!I11 -> 15115.789 | ... M9: ='Six Peak'!M11 -> 72490.789 | N9: =SUM(B9:M9) -> 379044.08
A10: APA (Six Peak share) | B10: =APA!B8 -> 0 | C10: =APA!C8 -> 0 | D10: =APA!D8 -> 800 | E10: =APA!E8 -> 0 | F10: =APA!F8 -> 0 | G10: =APA!G8 -> 0 | H10: =APA!H8 -> 0 | I10: =APA!I8 -> 0 | ... M10: =APA!M8 -> 0 | N10: =SUM(B10:M10) -> 800
A11: Total net revenue | B11: =SUM(B6:B10) -> 692483.05 | C11: =SUM(C6:C10) -> 724901.96 | D11: =SUM(D6:D10) -> 744176.58 | E11: =SUM(E6:E10) -> 504623.01 | F11: =SUM(F6:F10) -> 688754.15 | G11: =SUM(G6:G10) -> 595429.07 | H11: =SUM(H6:H10) -> 1238321.8 | I11: =SUM(I6:I10) -> 1134619.7 | ... M11: =SUM(M6:M10) -> 1353209.8 | N11: =SUM(B11:M11) -> 11295778
A12: EXPENSES
A13: LV payroll and burden, incl. $200K December bonus pool | B13: =SUM(LV!B53:B57)+LV!B84 -> -307682.01 | C13: =SUM(LV!C53:C57)+LV!C84 -> -319275.76 | D13: =SUM(LV!D53:D57)+LV!D84 -> -319275.76 | E13: =SUM(LV!E53:E57)+LV!E84 -> -334115.76 | F13: =SUM(LV!F53:F57)+LV!F84 -> -360549.51 | G13: =SUM(LV!G53:G57)+LV!G84 -> -413880.76 | H13: =SUM(LV!H53:H57)+LV!H84 -> -413880.76 | I13: =SUM(LV!I53:I57)+LV!I84 -> -413880.76 | ... M13: =SUM(LV!M53:M57)+LV!M84 -> -669067.01 | N13: =SUM(B13:M13) -> -4903622.9
A14: Six Peak payroll and burden | B14: =SUM('Six Peak'!B13:B17) -> -72134.875 | C14: =SUM('Six Peak'!C13:C17) -> -72134.875 | D14: =SUM('Six Peak'!D13:D17) -> -72134.875 | E14: =SUM('Six Peak'!E13:E17) -> -72134.875 | F14: =SUM('Six Peak'!F13:F17) -> -72134.875 | G14: =SUM('Six Peak'!G13:G17) -> -72134.875 | H14: =SUM('Six Peak'!H13:H17) -> -72134.875 | I14: =SUM('Six Peak'!I13:I17) -> -72134.875 | ... M14: =SUM('Six Peak'!M13:M17) -> -72134.875 | N14: =SUM(B14:M14) -> -865618.5
A15: Partner consulting fees | B15: ='Six Peak'!B34 -> -66666.667 | C15: ='Six Peak'!C34 -> -66666.667 | D15: ='Six Peak'!D34 -> -66666.667 | E15: ='Six Peak'!E34 -> -66666.667 | F15: ='Six Peak'!F34 -> -66666.667 | G15: ='Six Peak'!G34 -> -66666.667 | H15: ='Six Peak'!H34 -> -66666.667 | I15: ='Six Peak'!I34 -> -66666.667 | ... M15: ='Six Peak'!M34 -> -66666.667 | N15: =SUM(B15:M15) -> -800000
A16: Consultants (LV and Six Peak) | B16: =LV!B58+'Six Peak'!B29 -> -44750 | C16: =LV!C58+'Six Peak'!C29 -> -44750 | D16: =LV!D58+'Six Peak'!D29 -> -44750 | E16: =LV!E58+'Six Peak'!E29 -> -44750 | F16: =LV!F58+'Six Peak'!F29 -> -44750 | G16: =LV!G58+'Six Peak'!G29 -> -44750 | H16: =LV!H58+'Six Peak'!H29 -> -44750 | I16: =LV!I58+'Six Peak'!I29 -> -44750 | ... M16: =LV!M58+'Six Peak'!M29 -> -44750 | N16: =SUM(B16:M16) -> -537000
A17: Rent (LV office; Six Peak incl. NYC through April) | B17: =LV!B59+'Six Peak'!B18 -> -23500 | C17: =LV!C59+'Six Peak'!C18 -> -21750 | D17: =LV!D59+'Six Peak'!D18 -> -21750 | E17: =LV!E59+'Six Peak'!E18 -> -21750 | F17: =LV!F59+'Six Peak'!F18 -> -20000 | G17: =LV!G59+'Six Peak'!G18 -> -20000 | H17: =LV!H59+'Six Peak'!H18 -> -20000 | I17: =LV!I59+'Six Peak'!I18 -> -20000 | ... M17: =LV!M59+'Six Peak'!M18 -> -20000 | N17: =SUM(B17:M17) -> -248750
A18: Pay-app automation (Grind Phase 1) | B18: =LV!B83 -> -27500 | C18: =LV!C83 -> -27500 | D18: =LV!D83 -> -4000 | E18: =LV!E83 -> -4000 | F18: =LV!F83 -> -4000 | G18: =LV!G83 -> -4000 | H18: =LV!H83 -> -4000 | I18: =LV!I83 -> -4000 | ... M18: =LV!M83 -> -4000 | N18: =SUM(B18:M18) -> -95000
A19: Recruiting fees and BD commission | B19: =LV!B71+LV!B82 -> 0 | C19: =LV!C71+LV!C82 -> -9375 | D19: =LV!D71+LV!D82 -> 0 | E19: =LV!E71+LV!E82 -> -12000 | F19: =LV!F71+LV!F82 -> -21375 | G19: =LV!G71+LV!G82 -> -43125 | H19: =LV!H71+LV!H82 -> 0 | I19: =LV!I71+LV!I82 -> 0 | ... M19: =LV!M71+LV!M82 -> 0 | N19: =SUM(B19:M19) -> -193065.83
A20: Other overhead (insurance, legal, accounting, IT, office, travel, taxes) | B20: =B21-SUM(B13:B19) -> -73538.28 | C20: =C21-SUM(C13:C19) -> -73538.28 | D20: =D21-SUM(D13:D19) -> -73538.28 | E20: =E21-SUM(E13:E19) -> -73538.28 | F20: =F21-SUM(F13:F19) -> -73538.28 | G20: =G21-SUM(G13:G19) -> -73538.28 | H20: =H21-SUM(H13:H19) -> -73538.28 | I20: =I21-SUM(I13:I19) -> -73538.28 | ... M20: =M21-SUM(M13:M19) -> -73538.28 | N20: =SUM(B20:M20) -> -882459.36
A21: Total expenses | B21: =LV!B85+'Six Peak'!B37+APA!B9 -> -615771.83 | C21: =LV!C85+'Six Peak'!C37+APA!C9 -> -634990.58 | D21: =LV!D85+'Six Peak'!D37+APA!D9 -> -602115.58 | E21: =LV!E85+'Six Peak'!E37+APA!E9 -> -628955.58 | F21: =LV!F85+'Six Peak'!F37+APA!F9 -> -663014.33 | G21: =LV!G85+'Six Peak'!G37+APA!G9 -> -738095.58 | H21: =LV!H85+'Six Peak'!H37+APA!H9 -> -694970.58 | I21: =LV!I85+'Six Peak'!I37+APA!I9 -> -694970.58 | ... M21: =LV!M85+'Six Peak'!M37+APA!M9 -> -950156.83 | N21: =SUM(B21:M21) -> -8525516.6
A22: NET INCOME
A23: LV | B23: =LV!B86 -> 240471.07 | C23: =LV!C86 -> 248763.34 | D23: =LV!D86 -> 300112.96 | E23: =LV!E86 -> 34519.38 | F23: =LV!F86 -> 182841.77 | G23: =LV!G86 -> 14435.438 | H23: =LV!H86 -> 724359.42 | I23: =LV!I86 -> 620657.36 | ... M23: =LV!M86 -> 526686.21 | N23: =SUM(B23:M23) -> 4752654.9
A24: Six Peak | B24: ='Six Peak'!B38 -> -163759.85 | C24: ='Six Peak'!C38 -> -158851.96 | D24: ='Six Peak'!D38 -> -158851.96 | E24: ='Six Peak'!E38 -> -158851.96 | F24: ='Six Peak'!F38 -> -157101.96 | G24: ='Six Peak'!G38 -> -157101.96 | H24: ='Six Peak'!H38 -> -181008.21 | I24: ='Six Peak'!I38 -> -181008.21 | ... M24: ='Six Peak'!M38 -> -123633.21 | N24: =SUM(B24:M24) -> -1983193.9
A25: APA (Six Peak share) | B25: =APA!B10 -> 0 | C25: =APA!C10 -> 0 | D25: =APA!D10 -> 800 | E25: =APA!E10 -> 0 | F25: =APA!F10 -> 0 | G25: =APA!G10 -> 0 | H25: =APA!H10 -> 0 | I25: =APA!I10 -> 0 | ... M25: =APA!M10 -> 0 | N25: =SUM(B25:M25) -> 800
A26: CONSOLIDATED NET INCOME | B26: =SUM(B23:B25) -> 76711.218 | C26: =SUM(C23:C25) -> 89911.38 | D26: =SUM(D23:D25) -> 142061 | E26: =SUM(E23:E25) -> -124332.58 | F26: =SUM(F23:F25) -> 25739.813 | G26: =SUM(G23:G25) -> -142666.52 | H26: =SUM(H23:H25) -> 543351.21 | I26: =SUM(I23:I25) -> 439649.15 | ... M26: =SUM(M23:M25) -> 403053 | N26: =SUM(B26:M26) -> 2770261
A28: CASH: INS AND OUTS
A29: Opening cash | B29: 1786036.5 | C29: =B38 -> 210374.72 | D29: =C38 -> 234071.98 | E29: =D38 -> 319227.03 | F29: =E38 -> 391097.7 | G29: =F38 -> 187930.46 | H29: =G38 -> 109981.53 | I29: =H38 -> -77202.182 | J29: =I38 -> 376854.15 | ... M29: =L38 -> 1039991.6 | N29: =B29 -> 1786036.5
A30: Consolidated net income | B30: =B26 -> 76711.218 | C30: =C26 -> 89911.38 | D30: =D26 -> 142061 | E30: =E26 -> -124332.58 | F30: =F26 -> 25739.813 | G30: =G26 -> -142666.52 | H30: =H26 -> 543351.21 | I30: =I26 -> 439649.15 | ... M30: =M26 -> 403053 | N30: =SUM(B30:M30) -> 2770261
A31: LV billing and collection timing (owners pay about a month after billing) | B31: -123484.61 | C31: -28806.976 | D31: -18031.56 | E31: 239250.91 | F31: -183650.09 | G31: 93849.18 | H31: -666290.09 | I31: 104349.46 | J31: 81033.431 | K31: -30802.505 | L31: -392915.35 | M31: 184566.38 | N31: =SUM(B31:M31) -> -740931.8
A32: Retention withheld by owners (5% of fee billing) | B32: -36473.449 | C32: -37407.143 | D32: -38874.388 | E32: -43047.67 | F32: -45256.967 | G32: -59559.081 | H32: -64244.831 | I32: -58757.808 | J32: -65612.249 | K32: -65827.514 | L32: -73212.298 | M32: -64035.952 | N32: =SUM(B32:M32) -> -652309.35
A33: Retention released at job completion | B33: 0 | C33: 0 | D33: 0 | E33: 0 | F33: 0 | G33: 30427.483 | H33: 0 | I33: 80815.528 | J33: 137452.79 | K33: 92237.867 | L33: 0 | M33: 0 | N33: =SUM(B33:M33) -> 340933.67
A34: Krueger bonding fee paid (Francis, Lexington and Acama, January) | B34: -1254835.4 | C34: 0 | D34: 0 | E34: 0 | F34: 0 | G34: 0 | H34: 0 | I34: 0 | J34: 0 | K34: 0 | L34: 0 | M34: 0 | N34: =SUM(B34:M34) -> -1254835.4
A35: Steyn facility payments ($112K/mo from Aug) | B35: 0 | C35: 0 | D35: 0 | E35: 0 | F35: 0 | G35: 0 | H35: 0 | I35: -112000 | J35: -112000 | K35: -112000 | L35: -112000 | M35: -112000 | N35: =SUM(B35:M35) -> -560000
A36: Tax distribution on FY2026 income | B36: -237579.61 | C36: 0 | D36: 0 | E36: 0 | F36: 0 | G36: 0 | H36: 0 | I36: 0 | J36: 0 | K36: 0 | L36: 0 | M36: 0 | N36: =SUM(B36:M36) -> -237579.61
A37: Net cash flow | B37: =SUM(B30:B36) -> -1575661.8 | C37: =SUM(C30:C36) -> 23697.261 | D37: =SUM(D30:D36) -> 85155.052 | E37: =SUM(E30:E36) -> 71870.67 | F37: =SUM(F30:F36) -> -203167.24 | G37: =SUM(G30:G36) -> -77948.935 | H37: =SUM(H30:H36) -> -187183.71 | I37: =SUM(I30:I36) -> 454056.33 | ... M37: =SUM(M30:M36) -> 411583.43 | N37: =SUM(B37:M37) -> -334461.47
A38: Closing cash | B38: =B29+B37 -> 210374.72 | C38: =C29+C37 -> 234071.98 | D38: =D29+D37 -> 319227.03 | E38: =E29+E37 -> 391097.7 | F38: =F29+F37 -> 187930.46 | G38: =G29+G37 -> 109981.53 | H38: =H29+H37 -> -77202.182 | I38: =I29+I37 -> 376854.15 | ... M38: =M29+M37 -> 1451575.1 | N38: =M38 -> 1451575.1
A40: Opening cash is the model's 31 Dec 2026 balance (from the 30 Sep 2026 ledger). Acama's $561,958 Krueger fee is held to January; developer fees to Six Peak and APA are received as earned.
A42: MEMO
A43: LV total billing, including pass-through trade cost | B43: =LV!B27 -> 5653414.3 | C43: =LV!C27 -> 5737029.1 | D43: =LV!D27 -> 6249137.3 | E43: =LV!E27 -> 6690394.4 | F43: =LV!F27 -> 7133494.7 | G43: =LV!G27 -> 8784632 | H43: =LV!H27 -> 10164046 | I43: =LV!I27 -> 9819205.8 | ... M43: =LV!M27 -> 11980854 | N43: =SUM(B43:M43) -> 1.0729833e+08

Sheet Key Assumptions
A1: FY2027 budget: key assumptions
A2: Recommended for board approval, 2 November 2026 (internal sign-off 26 Oct; revised 28 Oct)
A4: THE BUDGET
A5: FY2027 | E5: Net income
A6: LV | E6: =Consolidated!N23 -> 4752654.9
A7: Six Peak | E7: =Consolidated!N24 -> -1983193.9
A8: APA (Six Peak share) | E8: =Consolidated!N25 -> 800
A9: Consolidated | E9: =Consolidated!N26 -> 2770261
A10: Cash low point | E10: =MIN(Consolidated!B38:M38) -> -77202.182 | F10: July 2027
A11: Cash, December 2027 | E11: =Consolidated!M38 -> 1451575.1
A13: BASIS
A14: Plan | B14: September-close Base Case (Beverly included from Oct 2027), with Reseda. The Base Case projection is this budget. Excludes Uplifters and BD placeholder deals.
A15: Rollup | B15: LV, Six Peak, and APA at Six Peak's 50% share. No intercompany charges.
A17: JOBS
A18: Job | B18: Status | C18: Start | D18: Bonded | E18: FY2027 trade billing
A19: Ramsgate | B19: Building | C19: In place | D19: No | E19: =LV!N9 -> 6937555.3
A20: Califa | B20: Building | C20: In place | D20: Yes | E20: =LV!N10 -> 3397238.9
A21: Whipple | B21: Building | C21: In place | D21: Yes | E21: =LV!N11 -> 4526432.8
A22: Nelrose | B22: Building | C22: In place | D22: No | E22: =LV!N12 -> 779534.21
A23: Francis | B23: Building | C23: In place | D23: Yes | E23: =LV!N13 -> 13298805
A24: Lexington | B24: Building | C24: In place | D24: Yes | E24: =LV!N14 -> 8814654.4
A25: Riverton | B25: Building | C25: In place | D25: Yes | E25: =LV!N15 -> 9659295.2
A26: Acama | B26: City stop work; restart assumed | C26: Jun-27 | D26: Yes | E26: =LV!N16 -> 4338145.4
A27: Klump | B27: Equity committed | C27: Feb-27 | D27: No | E27: =LV!N17 -> 5189183.6
A28: Scott | B28: Equity committed | C28: Jan-27 | D28: No | E28: =LV!N18 -> 4564217
A29: Reseda | B29: Investor and debt being replaced | C29: Jun-27 | D29: Yes | E29: =LV!N19 -> 6370497.9
A30: Moorpark | B30: Awarded to HVN; no contract | C30: Apr-27 | D30: Yes | E30: =LV!N22 -> 8309226.1
A31: Riverton 75 | B31: Awarded to HVN; no contract | C31: May-27 | D31: Yes | E31: =LV!N21 -> 3966575.6
A32: Lemp | B32: Award pending (Dec 9) | C32: Sep-27 | D32: Yes | E32: =LV!N20 -> 1721898.7
A33: Kester | B33: Award pending (Dec 9) | C33: Oct-27 | D33: Yes | E33: =LV!N24 -> 1106092.7
A34: Troost | B34: Awarded; contract in final | C34: Dec-26 | D34: No | E34: =LV!N23 -> 9158972.7
A35: Beverly | B35: GC RFP; not awarded | C35: Oct-27 | D35: No | E35: =LV!N25 -> 2113813.2
A36: Total trade billing | E36: =SUM(E19:E35) -> 94252139
A37: Trade billing is cost passed through at cost; LV earns the fee below.
A39: LV REVENUE
A40: Fee | B40: 14% of the Cost of the Work (6% supervision, 6% fee, 2% admin). The model calculates it as 12.04% of the contract (GMP), because the GMP already includes the fee and other items. Same dollars.
A41: Trade cost | B41: Passed through at cost on LIHTC jobs. On Ramsgate and Nelrose, buyout savings are split 50/50 with the owner.
A42: Bonding | B42: Owner pays a 1.5% bond line (Reseda 2.0%). LV pays Krueger 3.25% and CBI about 0.73%. Bonds post at job start. Acama's bond was issued 12 Oct 2026 on its $22.07M GMP: bond line $326,200, CBI premium $155,409, Krueger cash $561,958 (paid January).
A44: EXPENSES
A45: LV payroll | B45: Staffing engine: crew follows job starts, and current staff move to new jobs as jobs finish. PMs and APMs overlap jobs for a job's last 5 months. A role is hired only when jobs need at least 0.75 of a person. No field engineers. No 2027 raises. $200K year-end bonus pool each December ($75K paid for 2026).
...

Sheet LV
A1: LV Construction: FY2027 budget (recommended for board approval; revised 28 Oct 2026)
A2: Base Case plan with Reseda and Beverly (September-close models). GL lines match the Actuals/Budget tabs so FY2027 budget vs actual is line for line.
A4: $ (Jan to Dec 2027) | B4: Jan-27 | C4: Feb-27 | D4: Mar-27 | E4: Apr-27 | F4: May-27 | G4: Jun-27 | H4: Jul-27 | I4: Aug-27 | J4: Sep-27 | K4: Oct-27 | L4: Nov-27 | M4: Dec-27 | N4: FY2027
A5: REVENUE
A6: Other GC Income (supervision + project admin) | B6: 413306.32 | C6: 423591.63 | D6: 443350.63 | E6: 490831.08 | F6: 515376.77 | G6: 680044.57 | H6: 733430.11 | I6: 670566.93 | J6: 744326.41 | K6: 747258.87 | L6: 829071.4 | M6: 726699.96 | N6: =SUM(B6:M6) -> 7417854.7
A7: GC Fee Income | B7: 316162.67 | C7: 324551.22 | D7: 334137.12 | E7: 370122.32 | F7: 389762.56 | G7: 511137.05 | H7: 551466.5 | I7: 504589.23 | J7: 567918.57 | K7: 569291.41 | L7: 635174.56 | M7: 554019.08 | N7: =SUM(B7:M7) -> 5628332.3
A8: Trades and site cost billing, by job
A9: Ramsgate | B9: 971939.79 | C9: 809808.44 | D9: 1050106.5 | E9: 858162.3 | F9: 677761.69 | G9: 619657.29 | H9: 833901.29 | I9: 832480.71 | J9: 283737.27 | K9: 0 | L9: 0 | M9: 0 | N9: =SUM(B9:M9) -> 6937555.3
A10: Califa | B10: 585157.97 | C10: 497554.02 | D10: 597185.64 | E10: 572361.81 | F10: 509265.9 | G10: 344727.54 | H10: 149345.54 | I10: 141640.49 | J10: 0 | K10: 0 | L10: 0 | M10: 0 | N10: =SUM(B10:M10) -> 3397238.9
A11: Whipple | B11: 515849.83 | C11: 492274.7 | D11: 347513.21 | E11: 326394.52 | F11: 251483.96 | G11: 612215.42 | H11: 871620.13 | I11: 588727.53 | J11: 374851.55 | K11: 145501.97 | L11: 0 | M11: 0 | N11: =SUM(B11:M11) -> 4526432.8
A12: Nelrose | B12: 280874.08 | C12: 251083.56 | D12: 95915.43 | E12: 80111.01 | F12: 54755.77 | G12: 16794.36 | H12: 0 | I12: 0 | J12: 0 | K12: 0 | L12: 0 | M12: 0 | N12: =SUM(B12:M12) -> 779534.21
A13: Francis | B13: 653798.18 | C13: 528908.03 | D13: 638138.2 | E13: 538967.17 | F13: 662393.2 | G13: 622572.88 | H13: 1116701.3 | I13: 713626.26 | J13: 2128085.4 | K13: 1344331.6 | L13: 2761329.6 | M13: 1589952.9 | N13: =SUM(B13:M13) -> 13298805
A14: Lexington | B14: 608390.91 | C14: 689649.86 | D14: 759449.54 | E14: 813162.42 | F14: 847037.51 | G14: 858612.78 | H14: 847037.51 | I14: 813162.42 | J14: 759449.54 | K14: 689649.86 | L14: 608390.91 | M14: 520661.15 | N14: =SUM(B14:M14) -> 8814654.4
A15: Riverton | B15: 771225.14 | C15: 849281.08 | D15: 909347.4 | E15: 947229.39 | F15: 960173.85 | G15: 947229.39 | H15: 909347.4 | I15: 849281.08 | J15: 771225.14 | K15: 680354.47 | L15: 582247.59 | M15: 482353.29 | N15: =SUM(B15:M15) -> 9659295.2
A16: Acama | B16: 0 | C16: 0 | D16: 0 | E16: 0 | F16: 0 | G16: 347239.47 | H16: 431977.13 | I16: 522674.45 | J16: 617366.96 | K16: 713427.98 | L16: 807921.83 | M16: 897537.58 | N16: =SUM(B16:M16) -> 4338145.4
A17: Klump | B17: 0 | C17: 196306.31 | D17: 256105.78 | E17: 320473.53 | F17: 386842.9 | G17: 452024.7 | H17: 512398.8 | I17: 564258.84 | J17: 604166.65 | K17: 629335.3 | L17: 637935.54 | M17: 629335.3 | N17: =SUM(B17:M17) -> 5189183.6
A18: Scott | B18: 154657.42 | C18: 201769.67 | D18: 252480.98 | E18: 304769.23 | F18: 356121.89 | G18: 403686.85 | H18: 444544.12 | I18: 475984.98 | J18: 495813.77 | K18: 502589.37 | L18: 495813.77 | M18: 475984.98 | N18: =SUM(B18:M18) -> 4564217
A19: Reseda | B19: 0 | C19: 0 | D19: 0 | E19: 0 | F19: 0 | G19: 556266.06 | H19: 665675.84 | I19: 781966.17 | J19: 903552.72 | K19: 1028579.5 | L19: 1154783.3 | M19: 1279674.3 | N19: =SUM(B19:M19) -> 6370497.9
A20: Lemp | B20: 0 | C20: 0 | D20: 0 | E20: 0 | F20: 0 | G20: 0 | H20: 0 | I20: 0 | J20: 291464.41 | K20: 380251.25 | L20: 475820.81 | M20: 574362.26 | N20: =SUM(B20:M20) -> 1721898.7
... A25: Beverly | B25: 0 | C25: 0 | D25: 0 | E25: 0 | F25: 0 | G25: 0 | H25: 0 | I25: 0 | J25: 0 | K25: 544360.8 | L25: 700625.21 | M25: 868827.18 | N25: =SUM(B25:M25) -> 2113813.2
A26: Total Trades and Site Cost Billing | B26: =B9+B10+B11+B12+B13+B14+B15+B16+B17+B18+B19+B20+B21+B22+B23+B24+B25 -> 4923945.3 | C26: =C9+C10+C11+C12+C13+C14+C15+C16+C17+C18+C19+C20+C21+C22+C23+C24+C25 -> 4988886.2 | D26: =D9+D10+D11+D12+D13+D14+D15+D16+D17+D18+D19+D20+D21+D22+D23+D24+D25 -> 5471649.5 | E26: =E9+E10+E11+E12+E13+E14+E15+E16+E17+E18+E19+E20+E21+E22+E23+E24+E25 -> 5829441 | F26: =F9+F10+F11+F12+F13+F14+F15+F16+F17+F18+F19+F20+F21+F22+F23+F24+F25 -> 6228355.4 | G26: =G9+G10+G11+G12+G13+G14+G15+G16+G17+G18+G19+G20+G21+G22+G23+G24+G25 -> 7593450.4 | H26: =H9+H10+H11+H12+H13+H14+H15+H16+H17+H18+H19+H20+H21+H22+H23+H24+H25 -> 8879149.3 | I26: =I9+I10+I11+I12+I13+I14+I15+I16+I17+I18+I19+I20+I21+I22+I23+I24+I25 -> 8644049.7 | ... N26: =N9+N10+N11+N12+N13+N14+N15+N16+N17+N18+N19+N20+N21+N22+N23+N24+N25 -> 94252139
A27: Total Revenues | B27: =B6+B7+B26 -> 5653414.3 | C27: =C6+C7+C26 -> 5737029.1 | D27: =D6+D7+D26 -> 6249137.3 | E27: =E6+E7+E26 -> 6690394.4 | F27: =F6+F7+F26 -> 7133494.7 | G27: =G6+G7+G26 -> 8784632 | H27: =H6+H7+H26 -> 10164046 | I27: =I6+I7+I26 -> 9819205.8 | ... N27: =N6+N7+N26 -> 1.0729833e+08
A28: COGS: trade and site costs, by job
A29: Ramsgate | B29: -1018620.4 | C29: -848702.18 | D29: -1100541.3 | E29: -899378.4 | F29: -710313.45 | G29: -649418.4 | H29: -873952.17 | I29: -872463.36 | J29: -297364.7 | K29: 0 | L29: 0 | M29: 0 | N29: =SUM(B29:M29) -> -7270754.4
A30: Califa | B30: -600275.89 | C30: -510408.64 | D30: -612614.31 | E30: -587149.14 | F30: -522423.11 | G30: -353633.79 | H30: -153203.98 | I30: -145299.86 | J30: 0 | K30: 0 | L30: 0 | M30: 0 | N30: =SUM(B30:M30) -> -3485008.7
A31: Whipple | B31: -526373.31 | C31: -502317.24 | D31: -354602.58 | E31: -333053.05 | F31: -256614.3 | G31: -624704.78 | H31: -889401.42 | I31: -600737.73 | J31: -382498.63 | K31: -148470.25 | L31: 0 | M31: 0 | N31: =SUM(B31:M31) -> -4618773.3
A32: Nelrose | B32: -281402.12 | C32: -251555.59 | D32: -96095.75 | E32: -80261.61 | F32: -54858.71 | G32: -16825.94 | H32: 0 | I32: 0 | J32: 0 | K32: 0 | L32: 0 | M32: 0 | N32: =SUM(B32:M32) -> -780999.72
A33: Francis | B33: -653599.65 | C33: -528747.41 | D33: -637944.42 | E33: -538803.5 | F33: -662192.06 | G33: -622383.82 | H33: -1116362.2 | I33: -713409.55 | J33: -2127439.2 | K33: -1343923.4 | L33: -2760491 | M33: -1589470 | N33: =SUM(B33:M33) -> -13294766
A34: Lexington | B34: -608358.09 | C34: -689612.65 | D34: -759408.56 | E34: -813118.55 | F34: -846991.8 | G34: -858566.46 | H34: -846991.8 | I34: -813118.55 | J34: -759408.56 | K34: -689612.65 | L34: -608358.09 | M34: -520633.06 | N34: =SUM(B34:M34) -> -8814178.8
A35: Riverton | B35: -771002.45 | C35: -849035.85 | D35: -909084.82 | E35: -946955.88 | F35: -959896.6 | G35: -946955.88 | H35: -909084.82 | I35: -849035.85 | J35: -771002.45 | K35: -680158.02 | L35: -582079.47 | M35: -482214.01 | N35: =SUM(B35:M35) -> -9656506.1
A36: Acama | B36: 0 | C36: 0 | D36: 0 | E36: 0 | F36: 0 | G36: -347239.47 | H36: -431977.13 | I36: -522674.45 | J36: -617366.96 | K36: -713427.98 | L36: -807921.83 | M36: -897537.58 | N36: =SUM(B36:M36) -> -4338145.4
A37: Klump | B37: 0 | C37: -196306.31 | D37: -256105.78 | E37: -320473.53 | F37: -386842.9 | G37: -452024.7 | H37: -512398.8 | I37: -564258.84 | J37: -604166.65 | K37: -629335.3 | L37: -637935.54 | M37: -629335.3 | N37: =SUM(B37:M37) -> -5189183.6
A38: Scott | B38: -154657.42 | C38: -201769.67 | D38: -252480.98 | E38: -304769.23 | F38: -356121.89 | G38: -403686.85 | H38: -444544.12 | I38: -475984.98 | J38: -495813.77 | K38: -502589.37 | L38: -495813.77 | M38: -475984.98 | N38: =SUM(B38:M38) -> -4564217
A39: Reseda | B39: 0 | C39: 0 | D39: 0 | E39: 0 | F39: 0 | G39: -556266.06 | H39: -665675.84 | I39: -781966.17 | J39: -903552.72 | K39: -1028579.5 | L39: -1154783.3 | M39: -1279674.3 | N39: =SUM(B39:M39) -> -6370497.9
A40: Lemp | B40: 0 | C40: 0 | D40: 0 | E40: 0 | F40: 0 | G40: 0 | H40: 0 | I40: 0 | J40: -291464.41 | K40: -380251.25 | L40: -475820.81 | M40: -574362.26 | N40: =SUM(B40:M40) -> -1721898.7
... A45: Beverly | B45: 0 | C45: 0 | D45: 0 | E45: 0 | F45: 0 | G45: 0 | H45: 0 | I45: 0 | J45: 0 | K45: -544360.8 | L45: -700625.21 | M45: -868827.18 | N45: =SUM(B45:M45) -> -2113813.2
A46: Total COGS | B46: =B29+B30+B31+B32+B33+B34+B35+B36+B37+B38+B39+B40+B41+B42+B43+B44+B45 -> -4996341.4 | C46: =C29+C30+C31+C32+C33+C34+C35+C36+C37+C38+C39+C40+C41+C42+C43+C44+C45 -> -5050706.1 | D46: =D29+D30+D31+D32+D33+D34+D35+D36+D37+D38+D39+D40+D41+D42+D43+D44+D45 -> -5544285.4 | E46: =E29+E30+E31+E32+E33+E34+E35+E36+E37+E38+E39+E40+E41+E42+E43+E44+E45 -> -5891772.5 | F46: =F29+F30+F31+F32+F33+F34+F35+F36+F37+F38+F39+F40+F41+F42+F43+F44+F45 -> -6278773.5 | G46: =G29+G30+G31+G32+G33+G34+G35+G36+G37+G38+G39+G40+G41+G42+G43+G44+G45 -> -7644129.8 | H46: =H29+H30+H31+H32+H33+H34+H35+H36+H37+H38+H39+H40+H41+H42+H43+H44+H45 -> -8940192.5 | I46: =I29+I30+I31+I32+I33+I34+I35+I36+I37+I38+I39+I40+I41+I42+I43+I44+I45 -> -8699196.1 | ... N46: =N29+N30+N31+N32+N33+N34+N35+N36+N37+N38+N39+N40+N41+N42+N43+N44+N45 -> -94759610
A47: BONDING AND DEAL TERMS
A48: Bonding program, net (Krueger cash fee; bond line less CBI premium) | B48: 0 | C48: 0 | D48: 0 | E48: -332539.87 | F48: -204464.98 | G48: -583586.3 | H48: 0 | I48: 0 | J48: -251994.15 | K48: -242893.28 | L48: 0 | M48: 0 | N48: =SUM(B48:M48) -> -1615478.6
A49: Trade cost true-up (LIHTC pass-through) | B49: -454.04 | C49: -443.06 | D49: -497.34 | E49: -481.05 | F49: -524.1 | G49: -508.89 | H49: -647.4 | I49: -505.81 | J49: -909.9 | K49: -641.89 | L49: -1039.46 | M49: -650.18 | N49: =SUM(B49:M49) -> -7303.12
...

Sheet Staffing
A1: LV staffing: active jobs and people by role, April 2026 to December 2027
A2: Requested by Chris Andresen (29 Oct 2026) to explain the FY2027 hires, the main expense item. Source: Base Case staffing engine and Personnel tab (models _2026-10-28). April 2026 is the first month of the model roster; payroll staffing schedules before June list only part of the team, so earlier months are not shown. "Needed" is the engine's requirement from the active jobs, including superintendent lead time before a start; a role is hired only when the need exceeds staff by 0.75 of a person, and PMs and APMs overlap a job's last 5 months.
A4: Month | B4: Apr 26 | C4: May 26 | D4: Jun 26 | E4: Jul 26 | F4: Aug 26 | G4: Sep 26 | H4: Oct 26 | I4: Nov 26 | J4: Dec 26 | K4: Jan 27 | L4: Feb 27 | M4: Mar 27 | N4: Apr 27 | O4: May 27 | P4: Jun 27 | Q4: Jul 27 | R4: Aug 27 | S4: Sep 27 | T4: Oct 27 | U4: Nov 27 | V4: Dec 27
A5: Active jobs | B5: 5 | C5: 5 | D5: 5 | E5: 5 | F5: 7 | G5: 8 | H5: 8 | I5: 8 | J5: 8 | K5: 9 | L5: 10 | M5: 10 | N5: 11 | O5: 12 | P5: 14 | Q5: 13 | R5: 13 | S5: 13 | T5: 14 | U5: 13 | V5: 13
A7: People on staff, by role
A8: Project managers | B8: 3 | C8: 3 | D8: 3 | E8: 3 | F8: 3 | G8: 3 | H8: 3 | I8: 3 | J8: 3 | K8: 3 | L8: 3 | M8: 3 | N8: 3 | O8: 3 | P8: 3 | Q8: 3 | R8: 3 | S8: 3 | T8: 4 | U8: 4 | V8: 4
A9: needed for the active jobs | B9: 1.6 | C9: 1.6 | D9: 1.6 | E9: 1.4 | F9: 2 | G9: 2.2 | H9: 2.2 | I9: 2.2 | J9: 2.5 | K9: 2.7 | L9: 3 | M9: 3 | N9: 3 | O9: 3.1 | P9: 3.8 | Q9: 3.8 | R9: 3.5 | S9: 3.7 | T9: 4.2 | U9: 4 | V9: 3.9
A10: Assistant project managers | B10: 1 | C10: 2 | D10: 2 | E10: 2 | F10: 1 | G10: 2 | H10: 2 | I10: 2 | J10: 2 | K10: 2 | L10: 2 | M10: 2 | N10: 2 | O10: 2 | P10: 3 | Q10: 3 | R10: 3 | S10: 3 | T10: 4 | U10: 4 | V10: 4
A11: needed for the active jobs | B11: 1.1 | C11: 1.1 | D11: 1.1 | E11: 1 | F11: 1.7 | G11: 2 | H11: 2 | I11: 2 | J11: 2.2 | K11: 2.3 | L11: 2.4 | M11: 2.4 | N11: 2.5 | O11: 2.7 | P11: 3.3 | Q11: 3.3 | R11: 3.2 | S11: 3.5 | T11: 4 | U11: 3.7 | V11: 3.6
A12: Superintendents | B12: 4 | C12: 5 | D12: 5 | E12: 6 | F12: 6 | G12: 7 | H12: 7 | I12: 7 | J12: 8 | K12: 8 | L12: 8 | M12: 8 | N12: 9 | O12: 10 | P12: 12 | Q12: 12 | R12: 12 | S12: 12 | T12: 13 | U12: 13 | V12: 13
A13: needed for the active jobs | B13: 4.4 | C13: 4.4 | D13: 4.4 | E13: 4.4 | F13: 6.1 | G13: 7 | H13: 7 | I13: 7 | J13: 7.9 | K13: 7.9 | L13: 8.8 | M13: 8.8 | N13: 9.6 | O13: 10.5 | P13: 12.2 | Q13: 12.2 | R13: 11.4 | S13: 12.2 | T13: 13.1 | U13: 12.2 | V13: 11.4
A14: Assistant superintendents | B14: 1 | C14: 1 | D14: 3 | E14: 3 | F14: 4 | G14: 4 | H14: 4 | I14: 4 | J14: 4 | K14: 4 | L14: 5 | M14: 5 | N14: 5 | O14: 6 | P14: 7 | Q14: 7 | R14: 7 | S14: 7 | T14: 8 | U14: 8 | V14: 8
A15: needed for the active jobs | B15: 2.2 | C15: 2.2 | D15: 2.2 | E15: 2.2 | F15: 3.7 | G15: 4.2 | H15: 4.2 | I15: 4.2 | J15: 4.7 | K15: 4.7 | L15: 5 | M15: 5 | N15: 5.5 | O15: 6 | P15: 7.5 | Q15: 7.5 | R15: 7.2 | S15: 7.7 | T15: 8.7 | U15: 8.2 | V15: 7.7
A16: Project coordinators | B16: 1 | C16: 1 | D16: 2 | E16: 2 | F16: 2 | G16: 2 | H16: 3 | I16: 3 | J16: 3 | K16: 3 | L16: 3 | M16: 3 | N16: 3 | O16: 3 | P16: 3 | Q16: 3 | R16: 3 | S16: 3 | T16: 3 | U16: 3 | V16: 3
A17: Operations and labor | B17: 4 | C17: 4 | D17: 4 | E17: 4 | F17: 4 | G17: 4 | H17: 4 | I17: 4 | J17: 4 | K17: 4 | L17: 4 | M17: 4 | N17: 4 | O17: 4 | P17: 4 | Q17: 4 | R17: 4 | S17: 4 | T17: 4 | U17: 4 | V17: 4
A18: Executives and office | B18: 3 | C18: 3 | D18: 3 | E18: 3 | F18: 3 | G18: 3 | H18: 3 | I18: 3 | J18: 3 | K18: 2 | L18: 2 | M18: 2 | N18: 2 | O18: 2 | P18: 2 | Q18: 2 | R18: 2 | S18: 2 | T18: 2 | U18: 2 | V18: 2
A19: Total people on staff | B19: =B8+B10+B12+B14+B16+B17+B18 -> 17 | C19: =C8+C10+C12+C14+C16+C17+C18 -> 19 | D19: =D8+D10+D12+D14+D16+D17+D18 -> 22 | E19: =E8+E10+E12+E14+E16+E17+E18 -> 23 | F19: =F8+F10+F12+F14+F16+F17+F18 -> 23 | G19: =G8+G10+G12+G14+G16+G17+G18 -> 25 | H19: =H8+H10+H12+H14+H16+H17+H18 -> 26 | I19: =I8+I10+I12+I14+I16+I17+I18 -> 26 | ... V19: =V8+V10+V12+V14+V16+V17+V18 -> 38
A20: Change in headcount (hires less departures) | C20: =C19-B19 -> 2 | D20: =D19-C19 -> 3 | E20: =E19-D19 -> 1 | F20: =F19-E19 -> 0 | G20: =G19-F19 -> 2 | H20: =H19-G19 -> 1 | I20: =I19-H19 -> 0 | J20: =J19-I19 -> 1 | ... V20: =V19-U19 -> 0
A22: LV payroll, 5000-1000 (incl. December bonus pool) | B22: 187694 | C22: 295949 | D22: 198646 | E22: 215852 | F22: 217611 | G22: 223657 | H22: 267964 | I22: 267964 | J22: 356298 | K22: 270881 | L22: 281298 | M22: 281298 | N22: 294631 | O22: 318381 | P22: 366298 | Q22: 366298 | R22: 366298 | S22: 366298 | T22: 415881 | U22: 415881 | V22: 615881
A23: Payroll per active job | B23: =B22/B5 -> 37538.8 | C23: =C22/C5 -> 59189.8 | D23: =D22/D5 -> 39729.2 | E23: =E22/E5 -> 43170.4 | F23: =F22/F5 -> 31087.286 | G23: =G22/G5 -> 27957.125 | H23: =H22/H5 -> 33495.5 | I23: =I22/I5 -> 33495.5 | ... V23: =V22/V5 -> 47375.462
A24: Active jobs per project manager | B24: =B5/B8 -> 1.6666667 | C24: =C5/C8 -> 1.6666667 | D24: =D5/D8 -> 1.6666667 | E24: =E5/E8 -> 1.6666667 | F24: =F5/F8 -> 2.3333333 | G24: =G5/G8 -> 2.6666667 | H24: =H5/H8 -> 2.6666667 | I24: =I5/I8 -> 2.6666667 | ... V24: =V5/V8 -> 3.25
A26: 2026 versus 2027
A27: Measure | B27: 2026 (Apr to Dec) | C27: 2027 | D27: Change
A28: Average active jobs | B28: =AVERAGE(B5:J5) -> 6.5555556 | C28: =AVERAGE(K5:V5) -> 12.083333 | D28: =C28-B28 -> 5.5277778
A29: Active jobs at year end | B29: =J5 -> 8 | C29: =V5 -> 13 | D29: =C29-B29 -> 5
A30: Average people on staff | B30: =AVERAGE(B19:J19) -> 23.111111 | C30: =AVERAGE(K19:V19) -> 32.333333 | D30: =C30-B30 -> 9.2222222
A31: People on staff at year end | B31: =J19 -> 27 | C31: =V19 -> 38 | D31: =C31-B31 -> 11
A32: Project managers, year end | B32: =J8 -> 3 | C32: =V8 -> 4 | D32: =C32-B32 -> 1
A33: Assistant project managers, year end | B33: =J10 -> 2 | C33: =V10 -> 4 | D33: =C33-B33 -> 2
A34: Superintendents, year end | B34: =J12 -> 8 | C34: =V12 -> 13 | D34: =C34-B34 -> 5
A35: Assistant superintendents, year end | B35: =J14 -> 4 | C35: =V14 -> 8 | D35: =C35-B35 -> 4
A36: Project coordinators, year end | B36: =J16 -> 3 | C36: =V16 -> 3 | D36: =C36-B36 -> 0
A37: Operations and labor, year end | B37: =J17 -> 4 | C37: =V17 -> 4 | D37: =C37-B37 -> 0
A38: Executives and office, year end | B38: =J18 -> 3 | C38: =V18 -> 2 | D38: =C38-B38 -> -1
A39: Average active jobs per project manager | B39: =AVERAGE(B5:J5)/AVERAGE(B8:J8) -> 2.1851852 | C39: =AVERAGE(K5:V5)/AVERAGE(K8:V8) -> 3.7179487 | D39: =C39-B39 -> 1.5327635
A40: Average active jobs per superintendent | B40: =AVERAGE(B5:J5)/AVERAGE(B12:J12) -> 1.0727273 | C40: =AVERAGE(K5:V5)/AVERAGE(K12:V12) -> 1.1153846 | D40: =C40-B40 -> 0.042657343
A41: LV payroll per active job, per month | B41: =SUM(B22:J22)/SUM(B5:J5) -> 37824.322 | C41: =SUM(K22:V22)/SUM(K5:V5) -> 30064.303 | D41: =C41-B41 -> -7760.0186
A43: Reading it: active jobs roughly double (about 6.6 a month on average from April to December 2026, about 12 in 2027) while people on staff grow by about 40%. Hiring follows job starts; it is not running ahead of them.
A44: Payroll per active job falls from about $38K a month to about $30K: the team is stretched further in 2027, mostly on project managers (about 2.2 jobs each in 2026, 3.7 in 2027).
A45: Superintendents stay at about one per job. The thin months are February to June 2027, when starts run ahead of hires; PMs and APMs cover.
...

Sheet Six Peak
A1: Six Peak Capital: draft FY2027 budget
A2: Parent company only. APA is budgeted as a subsidiary on its own tab.
A4: $ (Jan to Dec 2027) | B4: Jan-27 | C4: Feb-27 | D4: Mar-27 | E4: Apr-27 | F4: May-27 | G4: Jun-27 | H4: Jul-27 | I4: Aug-27 | J4: Sep-27 | K4: Oct-27 | L4: Nov-27 | M4: Dec-27 | N4: FY2027
A5: REVENUE
A6: Ramsgate Dev Fee - Construction | B6: 23906.25 | C6: 23906.25 | D6: 23906.25 | E6: 23906.25 | F6: 23906.25 | G6: 23906.25 | H6: 0 | I6: 0 | J6: 0 | K6: 0 | L6: 0 | M6: 0 | N6: =SUM(B6:M6) -> 143437.5
A7: Ramsgate Dev Fee - 20% Occ | B7: 0 | C7: 0 | D7: 0 | E7: 0 | F7: 0 | G7: 0 | H7: 0 | I7: 0 | J7: 0 | K7: 0 | L7: 0 | M7: 57375 | N7: =SUM(B7:M7) -> 57375
A8: 12th & Fir Developer Fee | B8: 8800 | C8: 8800 | D8: 8800 | E8: 8800 | F8: 8800 | G8: 8800 | H8: 8800 | I8: 8800 | J8: 8800 | K8: 8800 | L8: 8800 | M8: 8800 | N8: =SUM(B8:M8) -> 105600
A9: Klump Developer Fee | B9: 0 | C9: 3157.8947 | D9: 3157.8947 | E9: 3157.8947 | F9: 3157.8947 | G9: 3157.8947 | H9: 3157.8947 | I9: 3157.8947 | J9: 3157.8947 | K9: 3157.8947 | L9: 3157.8947 | M9: 3157.8947 | N9: =SUM(B9:M9) -> 34736.842
A10: Scott Developer Fee | B10: 3157.8947 | C10: 3157.8947 | D10: 3157.8947 | E10: 3157.8947 | F10: 3157.8947 | G10: 3157.8947 | H10: 3157.8947 | I10: 3157.8947 | J10: 3157.8947 | K10: 3157.8947 | L10: 3157.8947 | M10: 3157.8947 | N10: =SUM(B10:M10) -> 37894.737
A11: Total Six Peak Revenue | B11: =B6+B7+B8+B9+B10 -> 35864.145 | C11: =C6+C7+C8+C9+C10 -> 39022.039 | D11: =D6+D7+D8+D9+D10 -> 39022.039 | E11: =E6+E7+E8+E9+E10 -> 39022.039 | F11: =F6+F7+F8+F9+F10 -> 39022.039 | G11: =G6+G7+G8+G9+G10 -> 39022.039 | H11: =H6+H7+H8+H9+H10 -> 15115.789 | I11: =I6+I7+I8+I9+I10 -> 15115.789 | ... N11: =N6+N7+N8+N9+N10 -> 379044.08
A12: EXPENSES
A13: 5000-1000 Payroll | B13: -54791.667 | C13: -54791.667 | D13: -54791.667 | E13: -54791.667 | F13: -54791.667 | G13: -54791.667 | H13: -54791.667 | I13: -54791.667 | J13: -54791.667 | K13: -54791.667 | L13: -54791.667 | M13: -54791.667 | N13: =SUM(B13:M13) -> -657500
A14: 5000-1001 Payroll Taxes | B14: -3835.4167 | C14: -3835.4167 | D14: -3835.4167 | E14: -3835.4167 | F14: -3835.4167 | G14: -3835.4167 | H14: -3835.4167 | I14: -3835.4167 | J14: -3835.4167 | K14: -3835.4167 | L14: -3835.4167 | M14: -3835.4167 | N14: =SUM(B14:M14) -> -46025
A15: 5000-1002 Employee Benefits | B15: -12138 | C15: -12138 | D15: -12138 | E15: -12138 | F15: -12138 | G15: -12138 | H15: -12138 | I15: -12138 | J15: -12138 | K15: -12138 | L15: -12138 | M15: -12138 | N15: =SUM(B15:M15) -> -145656
A16: 5000-1003 Workers Comp | B16: -1095.8333 | C16: -1095.8333 | D16: -1095.8333 | E16: -1095.8333 | F16: -1095.8333 | G16: -1095.8333 | H16: -1095.8333 | I16: -1095.8333 | J16: -1095.8333 | K16: -1095.8333 | L16: -1095.8333 | M16: -1095.8333 | N16: =SUM(B16:M16) -> -13150
A17: 5000-1005 Payroll Servicing Fees | B17: -273.95833 | C17: -273.95833 | D17: -273.95833 | E17: -273.95833 | F17: -273.95833 | G17: -273.95833 | H17: -273.95833 | I17: -273.95833 | J17: -273.95833 | K17: -273.95833 | L17: -273.95833 | M17: -273.95833 | N17: =SUM(B17:M17) -> -3287.5
A18: 5100-1000 Rent Expense | B18: -8500 | C18: -6750 | D18: -6750 | E18: -6750 | F18: -5000 | G18: -5000 | H18: -5000 | I18: -5000 | J18: -5000 | K18: -5000 | L18: -5000 | M18: -5000 | N18: =SUM(B18:M18) -> -68750
A19: 5200-1000 Office Supplies and Expenses | B19: -583.8 | C19: -583.8 | D19: -583.8 | E19: -583.8 | F19: -583.8 | G19: -583.8 | H19: -583.8 | I19: -583.8 | J19: -583.8 | K19: -583.8 | L19: -583.8 | M19: -583.8 | N19: =SUM(B19:M19) -> -7005.6
A20: 5200-1053 IT Software and Subscriptions | B20: -1497.86 | C20: -1497.86 | D20: -1497.86 | E20: -1497.86 | F20: -1497.86 | G20: -1497.86 | H20: -1497.86 | I20: -1497.86 | J20: -1497.86 | K20: -1497.86 | L20: -1497.86 | M20: -1497.86 | N20: =SUM(B20:M20) -> -17974.32
A21: 5200-1060 Website Design | B21: -290 | C21: -290 | D21: -290 | E21: -290 | F21: -290 | G21: -290 | H21: -290 | I21: -290 | J21: -290 | K21: -290 | L21: -290 | M21: -290 | N21: =SUM(B21:M21) -> -3480
A22: 5200-1061 Website Hosting | B22: -245 | C22: -245 | D22: -245 | E22: -245 | F22: -245 | G22: -245 | H22: -245 | I22: -245 | J22: -245 | K22: -245 | L22: -245 | M22: -245 | N22: =SUM(B22:M22) -> -2940
A23: 5300-1000 Travel and Lodging | B23: -1179.5 | C23: -1179.5 | D23: -1179.5 | E23: -1179.5 | F23: -1179.5 | G23: -1179.5 | H23: -1179.5 | I23: -1179.5 | J23: -1179.5 | K23: -1179.5 | L23: -1179.5 | M23: -1179.5 | N23: =SUM(B23:M23) -> -14154
A24: 5300-1001 Public Transportation | B24: -366.3 | C24: -366.3 | D24: -366.3 | E24: -366.3 | F24: -366.3 | G24: -366.3 | H24: -366.3 | I24: -366.3 | J24: -366.3 | K24: -366.3 | L24: -366.3 | M24: -366.3 | N24: =SUM(B24:M24) -> -4395.6
... A36: 5900-1080 Bank Service Charges | B36: -446.63 | C36: -446.63 | D36: -446.63 | E36: -446.63 | F36: -446.63 | G36: -446.63 | H36: -446.63 | I36: -446.63 | J36: -446.63 | K36: -446.63 | L36: -446.63 | M36: -446.63 | N36: =SUM(B36:M36) -> -5359.56
A37: Total Six Peak Expenses | B37: =B13+B14+B15+B16+B17+B18+B19+B20+B21+B22+B23+B24+B25+B26+B27+B28+B29+B30+B31+B32+B33+B34+B35+B36 -> -199623.99 | C37: =C13+C14+C15+C16+C17+C18+C19+C20+C21+C22+C23+C24+C25+C26+C27+C28+C29+C30+C31+C32+C33+C34+C35+C36 -> -197873.99 | D37: =D13+D14+D15+D16+D17+D18+D19+D20+D21+D22+D23+D24+D25+D26+D27+D28+D29+D30+D31+D32+D33+D34+D35+D36 -> -197873.99 | E37: =E13+E14+E15+E16+E17+E18+E19+E20+E21+E22+E23+E24+E25+E26+E27+E28+E29+E30+E31+E32+E33+E34+E35+E36 -> -197873.99 | F37: =F13+F14+F15+F16+F17+F18+F19+F20+F21+F22+F23+F24+F25+F26+F27+F28+F29+F30+F31+F32+F33+F34+F35+F36 -> -196123.99 | G37: =G13+G14+G15+G16+G17+G18+G19+G20+G21+G22+G23+G24+G25+G26+G27+G28+G29+G30+G31+G32+G33+G34+G35+G36 -> -196123.99 | H37: =H13+H14+H15+H16+H17+H18+H19+H20+H21+H22+H23+H24+H25+H26+H27+H28+H29+H30+H31+H32+H33+H34+H35+H36 -> -196123.99 | I37: =I13+I14+I15+I16+I17+I18+I19+I20+I21+I22+I23+I24+I25+I26+I27+I28+I29+I30+I31+I32+I33+I34+I35+I36 -> -196123.99 | ... N37: =N13+N14+N15+N16+N17+N18+N19+N20+N21+N22+N23+N24+N25+N26+N27+N28+N29+N30+N31+N32+N33+N34+N35+N36 -> -2362237.9
A38: SIX PEAK NET INCOME | B38: =B11+B37 -> -163759.85 | C38: =C11+C37 -> -158851.96 | D38: =D11+D37 -> -158851.96 | E38: =E11+E37 -> -158851.96 | F38: =F11+F37 -> -157101.96 | G38: =G11+G37 -> -157101.96 | H38: =H11+H37 -> -181008.21 | I38: =I11+I37 -> -181008.21 | ... N38: =N11+N37 -> -1983193.9

Sheet APA
A1: Adam Polk Architects Inc. (subsidiary): draft FY2027 budget
A2: Six Peak's share rolls into the consolidated budget. Source: 2026-10-16 APA Inc. FY2027 budget, base case with Reseda (3rd Street design engagement does not happen). APA Inc. is 50% owned and not consolidated; its company budget is a memo below.
A4: $ (Jan to Dec 2027) | B4: Jan-27 | C4: Feb-27 | D4: Mar-27 | E4: Apr-27 | F4: May-27 | G4: Jun-27 | H4: Jul-27 | I4: Aug-27 | J4: Sep-27 | K4: Oct-27 | L4: Nov-27 | M4: Dec-27 | N4: FY2027
A5: SIX PEAK'S SHARE (rolls up)
A6: Services Fee (zero: FY2027 fee pool is negative) | B6: 0 | C6: 0 | D6: 0 | E6: 0 | F6: 0 | G6: 0 | H6: 0 | I6: 0 | J6: 0 | K6: 0 | L6: 0 | M6: 0 | N6: =SUM(B6:M6) -> 0
A7: 50% of FY2026 dividend (paid Mar 2027) | B7: 0 | C7: 0 | D7: 800 | E7: 0 | F7: 0 | G7: 0 | H7: 0 | I7: 0 | J7: 0 | K7: 0 | L7: 0 | M7: 0 | N7: =SUM(B7:M7) -> 800
A8: Total APA revenue to Six Peak | B8: =B6+B7 -> 0 | C8: =C6+C7 -> 0 | D8: =D6+D7 -> 800 | E8: =E6+E7 -> 0 | F8: =F6+F7 -> 0 | G8: =G6+G7 -> 0 | H8: =H6+H7 -> 0 | I8: =I6+I7 -> 0 | ... N8: =N6+N7 -> 800
A9: APA expenses at Six Peak (none) | B9: 0 | C9: 0 | D9: 0 | E9: 0 | F9: 0 | G9: 0 | H9: 0 | I9: 0 | J9: 0 | K9: 0 | L9: 0 | M9: 0 | N9: =SUM(B9:M9) -> 0
A10: APA NET INCOME (Six Peak share) | B10: =B8+B9 -> 0 | C10: =C8+C9 -> 0 | D10: =D8+D9 -> 800 | E10: =E8+E9 -> 0 | F10: =F8+F9 -> 0 | G10: =G8+G9 -> 0 | H10: =H8+H9 -> 0 | I10: =I8+I9 -> 0 | ... N10: =N8+N9 -> 800
A12: MEMO: APA Inc. revenue by contract (company, 100%)
A13: Reseda | B13: 16666.66 | C13: 10000 | D13: 10000 | E13: 10000 | F13: 10000 | G13: 4166 | H13: 4166 | I13: 4166 | J13: 4166 | K13: 4166 | L13: 4166 | M13: 4166 | N13: =SUM(B13:M13) -> 85828.66
A14: Francis | B14: 4166.66 | C14: 4166.66 | D14: 4166.66 | E14: 4166.66 | F14: 4166.66 | G14: 4166.66 | H14: 4166.66 | I14: 4166.66 | J14: 4166.66 | K14: 4166.66 | L14: 4166.66 | M14: 4166.66 | N14: =SUM(B14:M14) -> 49999.92
A15: Ramsgate | B15: 3332.72 | C15: 3332.72 | D15: 3332.72 | E15: 3332.72 | F15: 3332.72 | G15: 3332.72 | H15: 3332.72 | I15: 3332.72 | J15: 0 | K15: 0 | L15: 0 | M15: 0 | N15: =SUM(B15:M15) -> 26661.76
A16: 3rd Street (existing contract only) | B16: 9750 | C16: 0 | D16: 0 | E16: 0 | F16: 0 | G16: 0 | H16: 0 | I16: 0 | J16: 0 | K16: 0 | L16: 0 | M16: 0 | N16: =SUM(B16:M16) -> 9750
A17: APA Inc. total revenue | B17: =B13+B14+B15+B16 -> 33916.04 | C17: =C13+C14+C15+C16 -> 17499.38 | D17: =D13+D14+D15+D16 -> 17499.38 | E17: =E13+E14+E15+E16 -> 17499.38 | F17: =F13+F14+F15+F16 -> 17499.38 | G17: =G13+G14+G15+G16 -> 11665.38 | H17: =H13+H14+H15+H16 -> 11665.38 | I17: =I13+I14+I15+I16 -> 11665.38 | ... N17: =N13+N14+N15+N16 -> 172240.34
A19: MEMO: APA Inc. FY2027 annual waterfall (company, 100%)
A20: Revenue | N20: 172240.34
A21: Overhead | N21: 25000
A22: Polk Base Fee (paid first) | N22: 150000
A23: Polk Supplemental Fee | N23: 0
A24: Six Peak Services Fee | N24: 0
A25: California franchise tax | N25: 800
A26: Federal income tax | N26: 0
A27: Net income after tax | N27: -3559.66
A28: Dividend of FY2027 income (declared in FY2028) | N28: 0
A29: Six Peak 50% share of that dividend | N29: 0
A30: APA PC 50% share of that dividend | N30: 0
A31: Shortfall the Company must fund (loss year) | N31: 3559.66
A32: Polk Base Fee unpaid, accrued in APA Inc. (no Six Peak cash) | N32: 3559.66

Sheet Mgmt View (Hypothetical)
A1: Management view (hypothetical): Six Peak people cost allocated to LV
A2: HYPOTHETICAL ONLY. Six Peak does not charge LV for this time, and none of it is in the financials or in this budget. Six Peak's people do spend real time on LV, so from a management perspective this shows roughly what each business costs to run if that time were charged. Consolidated net income does not change.
A4: FY2027 | B4: Full cost | C4: Share of time on LV | D4: Allocated to LV
A5: Tom Taggart | B5: =-'Six Peak'!N29*222000/337000 -> 222000 | C5: 1 | D5: =B5*C5 -> 222000
A6: Robert Carrega | B6: =-(('Six Peak'!N13+'Six Peak'!N14+'Six Peak'!N16+'Six Peak'!N17)*157500/657500+'Six Peak'!N15/3) -> 221014.5 | C6: 0.9 | D6: =B6*C6 -> 198913.05
A7: Chris Andresen | B7: =-(('Six Peak'!N13+'Six Peak'!N14+'Six Peak'!N16+'Six Peak'!N17)*250000/657500+'Six Peak'!N15/3) -> 322302 | C7: 0.75 | D7: =B7*C7 -> 241726.5
A8: Chris Aiello | B8: =-'Six Peak'!N34/2 -> 400000 | C8: 0.5 | D8: =B8*C8 -> 200000
A9: Bob Kennedy | B9: =-'Six Peak'!N34/2 -> 400000 | C9: 0.1 | D9: =B9*C9 -> 40000
A10: Derek Sanders | B10: =-(('Six Peak'!N13+'Six Peak'!N14+'Six Peak'!N16+'Six Peak'!N17)*250000/657500+'Six Peak'!N15/3) -> 322302 | C10: 0.1 | D10: =B10*C10 -> 32230.2
A11: Total | B11: =SUM(B5:B10) -> 1887618.5 | D11: =SUM(D5:D10) -> 934869.75
A12: Full cost is salary and burden (or consulting fee) from the Six Peak tab; partners and Tom carry no benefits. Shares (blue) are inputs.
A14: FY2027 net income | B14: As budgeted | C14: Hypothetical allocation | D14: After allocation
A15: LV | B15: =Consolidated!N23 -> 4752654.9 | C15: =-D11 -> -934869.75 | D15: =B15+C15 -> 3817785.1
A16: Six Peak | B16: =Consolidated!N24 -> -1983193.9 | C16: =D11 -> 934869.75 | D16: =B16+C16 -> -1048324.1
A17: APA (Six Peak share) | B17: =Consolidated!N25 -> 800 | C17: 0 | D17: =B17+C17 -> 800
A18: Consolidated (unchanged) | B18: =SUM(B15:B17) -> 2770261 | C18: =SUM(C15:C17) -> 0 | D18: =SUM(D15:D17) -> 2770261

Sheet Source and checks
A1: Source and checks
A3: Source workbooks: SixPeak_BaseCase_2026-10-28.xlsx (Base Case = this budget), Target Business Plan and In-Place Floor of the same date. September 2026 close. | B3: Six Peak Projections - Base Case.xlsx and Target Business Plan.xlsx, 09.2026 Projections (September close, 16 Oct 2026; Reseda bond 20 Oct)
A4: Columns | B4: Model columns N:Y = Jan-Dec 2027; values frozen, totals are formulas
A5: Check: LV NI. Base Case Model row 237, FY2027 (models _2026-10-28). Should equal Consolidated!N23. | B5: 4752655
A6: Check: Six Peak NI. Base Case Model row 293, FY2027. Should equal Consolidated!N24. | B6: -1983194
A7: Older check values (LV 4,297,655 and consolidated 2,299,779) were pre-adjustment figures from the 20 Oct build; replaced 28 Oct with checks that tie to this budget.
A8: Check: APA NI = APA Inc. FY2027 budget file, row 65 (replaces Model row 297) | B8: 800
A9: Check: Consolidated NI. Base Case Model row 308, FY2027, less the APA difference ($915 on the model APA schedule vs $800 in the APA Inc. budget file). Should equal Consolidated!N26. | B9: 2770261
A10: Check: hypothetical allocation nets to zero (Mgmt View) | B10: =ROUND('Mgmt View (Hypothetical)'!C15+'Mgmt View (Hypothetical)'!C16,2) -> 0
A11: Check: consolidated = total net revenue + total expenses | B11: =ROUND(Consolidated!N26-Consolidated!N11-Consolidated!N21,2) -> 0
A12: Expense review applied (October): LV rent $15K/mo, LV benefits 3.5%, LV workers comp 0.3%, recruiter fees 7.5%, LV state tax $1,250/mo base; Six Peak benefits $12,138/mo, legal $3,750, misc $3,333, entity fees $3,333 base.
A13: Uplifters removed (program dropped); Schuyler Dietz stays a Six Peak consultant at $115K.
A14: APA replaced: Model row 297 carries 131,310 (old APA schedule with 3rd Street); this budget uses the APA Inc. base case (with Reseda), 800. Model consolidated 2,520,259 less 130,510 = 2,389,749.
A15: Beverly added 20 Oct 2026, start moved to October 2027 (Projects!C20 = 19): 09.2026 Target Business Plan rerun (LibreOffice full recalc, ties to the saved Excel values at the original start) less Base Case, Model N:Y. Trades billing/COGS rows 29/76 2,113,813 each (net zero); Other GC Income +204,450; GC Fee +153,337; payroll and burden rows 203-208 -122,040; Consulting Fee row 223 (placement) -32,250; BD Commission row 234 -62,566; ending cash row 383 applied to the memo cash month by month. LV NI +140,931. Bonding, Six Peak and APA unchanged.
A16: Pay-app automation added 20 Oct 2026, license revised 26 Oct 2026: Grind Analytics Phase 1, $47,000 one-time (memo 10/15/26) plus the platform license at $4,000/mo for the first 12 months (Jan-Dec 2027), stepping up to $5,550/mo from Jan 2028 (Chris, 26 Oct). New LV GC cost line: Jan and Feb -27,500 each (one-time 47,000 split evenly plus 4,000), Mar-Dec -4,000. FY2027 95,000 (was 113,600). Not in the projection model, so the model checks above are shown less 95,000. Memo cash reduced cumulatively.
A17: Reseda bond line at 2.0% (20 Oct 2026): Bonding Program I22 = 0.02 (model default 1.5%), rerun in LibreOffice. Bond line 668,967 -> 887,584; CBI premium (331,073) and Krueger cash (1,140,098) unchanged. LV gross profit +218,617 in Jun 2027 (Model row 196); cash collected Jul 2027 (memo cash +218,617 from Jul). Checks above include it.
A18: Acama slipped six months, 26 Oct 2026 (Chris): city stop work after start (LV Stop Work Notice 23 Oct); start Projects!C10 9 -> 15 (Dec 2026 -> Jun 2027), 24 months unchanged. Bond month pinned at Dec 2026 (Bonding Program G19 = 9): the Acama bond was issued 13 Oct 2026 (CBI), so the bonding program does not move into FY2027. Target Business Plan (Beverly Oct 2027) rerun in LibreOffice with and without the slip, Model N:Y deltas applied: Acama trades billing/COGS rows 21/68 -6,021,554 each (net zero); Other GC Income -289,516; GC Fee -217,136 (Jan-May 2027; Dec 2026 also lost in FY2026); payroll and burden rows 203-208 +182,634 (staffing engine hires later); Consulting Fee row 223 -21,750. LV NI -345,767 in FY2027 (and -52,683 in Dec 2026, which lowers the Jan 2027 tax distribution by 26,499). Ending cash row 383 applied to the memo cash month by month. Comparison blocks (with/without Reseda, with/without Beverly) rerun with the slip.
A19: NYC office (Six Peak), agreed 26 Oct 2026 (Bob Kennedy): full rent Nov 2026-Jan 2027, half rent Feb-Apr 2027, nothing after. Full rent taken as the model's $3,500/mo (Six Peak rent of $8,500/mo in Oct-Nov 2026 less the $5,000/mo Six Peak share of the LV office); the model had the NYC office ending 1 Dec 2026. Six Peak rent row 18: Jan -3,500, Feb-Apr -1,750 each, on top of $5,000/mo; FY2027 -8,750. Dec 2026 -3,500 lowers FY2026 NI and the Jan 2027 tax distribution by 1,761. Memo cash -10,489 from April on. Bob and Daniel are looking for someone to take over the space, which would end the rent early (not assumed).
A20: Check: LV gross profit ties (Consolidated lines vs LV tab) | B20: =ROUND(Consolidated!N6+Consolidated!N7+Consolidated!N8-LV!N51,2) -> 0
A21: Restructured 26 Oct 2026: Summary tab removed (content moved to Key Assumptions), Consolidated rebuilt with an expense breakdown, management allocation moved to its own hypothetical tab.
A23: Acama Krueger cash, 26 Oct 2026 (Chris): Acama's Krueger cash ($535,544 = 3.25% x $21,263,405 GMP less est. CBI premium $155,516) is paid with Francis and Lexington in January 2027, not in the Dec 2026 bond month. Opening cash 1 Jan 2027 +535,544; January Krueger payout 692,877 -> 1,228,421. Cost stays in FY2026 (bond issued 13 Oct 2026); FY2027 NI and month-end cash unchanged. Moorpark and Riverton 75 stay on the Krueger program.
A24: Staffing, 26 Oct 2026 (Chris): Priscilla Hernandez already hired as the Project Coordinator at $100,000 (replaces the planned PC add; on payroll from Oct 2026, no 2027 placement fee). PM/APM wind-down overlap 3 -> 5 months (Staffing B106 = 5); hire trigger tolerance 0.25 -> 0.75 (a role is hired only when demand exceeds staff by 0.75 of a person, B18); field engineers removed (gates B22/B23 = 99). Alex Rodriquez reassigned during the Acama delay (the engine already pools named supers). New hires 18 -> 13. LV NI FY2027 +554,395 vs the pre-staffing-change budget; FY2026 -14,356, so opening cash -14,356 and the Jan 2027 tax distribution -7,221. Superintendent coverage is thinner Feb-Jun 2027 (up to 2 more active jobs than superintendents, vs 1 before).
A25: Raises and bonus, 26 Oct 2026 (Chris): no 2027 raises for LV (the model's 2% April step on LV payroll, burden and consultants is unwound); Six Peak 0% except Robert Carrega +5% from January ($150,000 -> $157,500); the April 2% is unwound on Six Peak payroll, Tom/Schuyler consulting and partner fees. LV year-end bonus pool $200,000 in Dec 2027 (all-in, own LV line). A $75,000 LV bonus is assumed paid in Dec 2026: opening cash -75,000 and the Jan 2027 tax distribution -37,725 (50.3%).
A26: 26 Oct 2026: the model's 2% April expense escalation is removed in both companies (LV non-payroll overhead rows and Six Peak overhead rows, Apr-Dec / 1.02). Placeholder cost codes assigned to the three budget-only LV lines: 5800-1010 BD Commission, 5200-1056 Pay-App Automation, 5000-1010 Year-End Bonus Pool (confirm against the chart of accounts).
A27: Tie to the Base Case (26 Oct 2026, after the FY2027 assumptions were loaded into the 09.2026 plan workbooks, models _2026-10-26): LV burden on Priscilla Hernandez's $100,000 salary trued up to the model (+$848 FY2027) and opening cash aligned to the model's 31 Dec 2026 balance. Remaining difference: APA $115 (model APA schedule $915 vs the APA Inc. budget file $800). Base Case FY2027 consolidated NI = this budget + $115.
A28: What-moves-it figures rerun 26 Oct 2026 on the final Base Case (models _2026-10-26): Reseda off -320,878; Beverly off -97,401; Acama at the Dec 2026 start +409,364 (so the slip costs 409,364).
A29: 28 Oct 2026 (Chris): (1) Acama on its $22,072,845 GMP (Projects!B10; was $21,263,405) with actual bond figures: bond issued 12 Oct 2026, bond line $326,200 (invoice LV-2026-ACA-01), CBI premium $155,409 (invoice #024003), Krueger cash $561,958 (615 Holdings schedule 28 Oct); bond month Oct 2026 (was Dec 2026). (2) 12th & Fir developer fee $8,800 a month (was $9,500), Jul 2026 to Sep 2028 (Chris Andresen, 29 Oct). (3) Staffing engine superintendent slots 6-10 priced at $160,000 (were at the assistant superintendent rate, $125,000); affects the Oct 2027 superintendent. FY2026 NI -14,345; FY2027 LV NI +14,638 (GMP fee +27,001 less superintendent -12,364); Krueger January payout 1,228,421 -> 1,254,835; tax distribution 245,851 -> 238,636; opening cash 1 Jan 2027 -364,753 (bond net cost now runs through cash in Oct-Nov 2026 instead of January).
A30: Check: consolidated NI less the model check (0 = ties) | B30: =ROUND(Consolidated!N26-B9,0) -> 0
A31: Check: LV NI less the model check (0 = ties) | B31: =ROUND(Consolidated!N23-B5,0) -> 0
A32: Check: Dec 2027 closing cash less Base Case Model row 383 Dec-27, less the $115 APA difference (0 = ties) | B32: =ROUND(Consolidated!M38-(1451690.4510566-115),0) -> 0
